Workbook

Sheet Votos por partido
A2: Paso 2017 | I2: General 2017 | Q2: General 2019
A3: Circuito | B3: SANTA ROSA | C3: Categoria | D3: Destino | E3: Cantidad | F3: TOTAL | G3: PADRON | I3: Circuito | J3: SANTA ROSA | K3: Categoria | L3: Destino | M3: Cantidad | N3: TOTAL | O3: PADRON | Q3: Circuito | R3: SANTA ROSA | S3: Categoria | T3: Destino | U3: Cantidad | V3: TOTAL | W3: PADRON
A4: 9 y 10 | B4: SANTA ROSA | C4: Diputado Nac. | D4: PJ | E4: 22866 | G4: 90619 | I4: 9 y 10 | J4: SANTA ROSA | K4: Diputado Nac. | L4: PJ | M4: 29146 | O4: 90619 | Q4: 9 y 10 | R4: SANTA ROSA | S4: Gobernador | T4: PJ | U4: 33285 | V4: =SUM(U4:U13) -> 65565 | W4: 90434
A5: 9 y 10 | B5: SANTA ROSA | C5: Diputado Nac. | D5: Humanista | E5: 2397 | I5: 9 y 10 | J5: SANTA ROSA | K5: Diputado Nac. | L5: Humanista | M5: 2051 | Q5: 9 y 10 | R5: SANTA ROSA | S5: Gobernador | T5: Cambiemos - FREPAM | U5: 16400
A6: 9 y 10 | B6: SANTA ROSA | C6: Diputado Nac. | D6: Partido de los Trabajadores Soc. | E6: 1989 | I6: 9 y 10 | J6: SANTA ROSA | K6: Diputado Nac. | L6: Partido de los Trabajadores Soc. | M6: 2160 | Q6: 9 y 10 | R6: SANTA ROSA | S6: Gobernador | T6: Comunidad organizada | U6: 7012
A7: 9 y 10 | B7: SANTA ROSA | C7: Diputado Nac. | D7: FREPAM | E7: 2448 | I7: 9 y 10 | J7: SANTA ROSA | K7: Diputado Nac. | L7: FREPAM | M7: 2075 | Q7: 9 y 10 | R7: SANTA ROSA | S7: Gobernador | T7: Pueblo Nuevo | U7: 2216
A8: 9 y 10 | B8: SANTA ROSA | C8: Diputado Nac. | D8: Izquierda al Frente por el Soc. | E8: 1479 | I8: 9 y 10 | J8: SANTA ROSA | K8: Diputado Nac. | L8: Izquierda al Frente por el Soc. | M8: 1794 | Q8: 9 y 10 | R8: SANTA ROSA | S8: Gobernador | T8: Blanco | U8: 1706
A9: 9 y 10 | B9: SANTA ROSA | C9: Diputado Nac. | D9: Cambiemos | E9: 30769 | I9: 9 y 10 | J9: SANTA ROSA | K9: Diputado Nac. | L9: Cambiemos | M9: 28965 | Q9: 9 y 10 | R9: SANTA ROSA | S9: Gobernador | T9: Partido socialista | U9: 1655
A10: 9 y 10 | B10: SANTA ROSA | C10: Diputado Nac. | D10: Nulo | E10: 2428 | I10: 9 y 10 | J10: SANTA ROSA | K10: Diputado Nac. | L10: Nulo | M10: 1458 | Q10: 9 y 10 | R10: SANTA ROSA | S10: Gobernador | T10: Frente popular pampeano | U10: 1144
A11: 9 y 10 | B11: SANTA ROSA | C11: Diputado Nac. | D11: Blanco | E11: 878 | F11: 65254 | I11: 9 y 10 | J11: SANTA ROSA | K11: Diputado Nac. | L11: Blanco | M11: 540 | N11: 68264 | Q11: 9 y 10 | R11: SANTA ROSA | S11: Gobernador | T11: Nulo | U11: 801
A12: 58 | B12: GENERAL PICO | C12: Diputado Nac. | D12: PJ | E12: 11755 | G12: 50143 | I12: 58 | J12: GENERAL PICO | K12: Diputado Nac. | L12: PJ | M12: 16967 | O12: 50143 | Q12: 9 y 10 | R12: SANTA ROSA | S12: Gobernador | T12: Movimiento socialista de los trabajadores | U12: 743
A13: 58 | B13: GENERAL PICO | C13: Diputado Nac. | D13: Humanista | E13: 675 | I13: 58 | J13: GENERAL PICO | K13: Diputado Nac. | L13: Humanista | M13: 538 | Q13: 9 y 10 | R13: SANTA ROSA | S13: Gobernador | T13: Desde el pie | U13: 603
A14: 58 | B14: GENERAL PICO | C14: Diputado Nac. | D14: Partido de los Trabajadores Soc. | E14: 518 | I14: 58 | J14: GENERAL PICO | K14: Diputado Nac. | L14: Partido de los Trabajadores Soc. | M14: 486 | Q14: 57 y 58 | R14: GENERAL PICO | S14: Gobernador | T14: PJ | U14: 18299 | V14: =SUM(U14:U23) -> 38282 | W14: 50004
A15: 58 | B15: GENERAL PICO | C15: Diputado Nac. | D15: FREPAM | E15: 3294 | I15: 58 | J15: GENERAL PICO | K15: Diputado Nac. | L15: FREPAM | M15: 2915 | Q15: 57 y 58 | R15: GENERAL PICO | S15: Gobernador | T15: Cambiemos - FREPAM | U15: 11117
A16: 58 | B16: GENERAL PICO | C16: Diputado Nac. | D16: Izquierda al Frente por el Soc. | E16: 851 | I16: 58 | J16: GENERAL PICO | K16: Diputado Nac. | L16: Izquierda al Frente por el Soc. | M16: 764 | Q16: 57 y 58 | R16: GENERAL PICO | S16: Gobernador | T16: Pueblo Nuevo | U16: 2022
A17: 58 | B17: GENERAL PICO | C17: Diputado Nac. | D17: Cambiemos | E17: 18453 | I17: 58 | J17: GENERAL PICO | K17: Diputado Nac. | L17: Cambiemos | M17: 16986 | Q17: 57 y 58 | R17: GENERAL PICO | S17: Gobernador | T17: Blanco | U17: 1981
A18: 58 | B18: GENERAL PICO | C18: Diputado Nac. | D18: Nulo | E18: 1499 | I18: 58 | J18: GENERAL PICO | K18: Diputado Nac. | L18: Nulo | M18: 797 | Q18: 57 y 58 | R18: GENERAL PICO | S18: Gobernador | T18: Comunidad organizada | U18: 1949
A19: 58 | B19: GENERAL PICO | C19: Diputado Nac. | D19: Blanco | E19: 638 | F19: =SUM(E12:E19) -> 37683 | I19: 58 | J19: GENERAL PICO | K19: Diputado Nac. | L19: Blanco | M19: 301 | N19: 39754 | Q19: 57 y 58 | R19: GENERAL PICO | S19: Gobernador | T19: Desde el pie | U19: 713
A20: 93 | B20: GRAL ACHA | C20: Diputado Nac. | D20: PJ | E20: 2319 | G20: 11653 | I20: 93 | J20: GRAL ACHA | K20: Diputado Nac. | L20: PJ | M20: 3096 | O20: 11653 | Q20: 57 y 58 | R20: GENERAL PICO | S20: Gobernador | T20: Frente popular pampeano | U20: 687
A21: 93 | B21: GRAL ACHA | C21: Diputado Nac. | D21: Humanista | E21: 102 | I21: 93 | J21: GRAL ACHA | K21: Diputado Nac. | L21: Humanista | M21: 107 | Q21: 57 y 58 | R21: GENERAL PICO | S21: Gobernador | T21: Partido socialista | U21: 627
A22: 93 | B22: GRAL ACHA | C22: Diputado Nac. | D22: Partido de los Trabajadores Soc. | E22: 102 | I22: 93 | J22: GRAL ACHA | K22: Diputado Nac. | L22: Partido de los Trabajadores Soc. | M22: 133 | Q22: 57 y 58 | R22: GENERAL PICO | S22: Gobernador | T22: Nulo | U22: 536
A23: 93 | B23: GRAL ACHA | C23: Diputado Nac. | D23: FREPAM | E23: 239 | I23: 93 | J23: GRAL ACHA | K23: Diputado Nac. | L23: FREPAM | M23: 195 | Q23: 57 y 58 | R23: GENERAL PICO | S23: Gobernador | T23: Movimiento socialista de los trabajadores | U23: 351
A24: 93 | B24: GRAL ACHA | C24: Diputado Nac. | D24: Izquierda al Frente por el Soc. | E24: 175 | I24: 93 | J24: GRAL ACHA | K24: Diputado Nac. | L24: Izquierda al Frente por el Soc. | M24: 175 | Q24: 93 | R24: GRAL ACHA | S24: Gobernador | T24: PJ | U24: 3191 | V24: =SUM(U24:U33) -> 8822 | W24: 11574
A25: 93 | B25: GRAL ACHA | C25: Diputado Nac. | D25: Cambiemos | E25: 4528 | I25: 93 | J25: GRAL ACHA | K25: Diputado Nac. | L25: Cambiemos | M25: 4527 | Q25: 93 | R25: GRAL ACHA | S25: Gobernador | T25: Cambiemos - FREPAM | U25: 2793
A26: 93 | B26: GRAL ACHA | C26: Diputado Nac. | D26: Nulo | E26: 490 | I26: 93 | J26: GRAL ACHA | K26: Diputado Nac. | L26: Nulo | M26: 233 | Q26: 93 | R26: GRAL ACHA | S26: Gobernador | T26: Blanco | U26: 1541
A27: 93 | B27: GRAL ACHA | C27: Diputado Nac. | D27: Blanco | E27: 177 | F27: =SUM(E20:E27) -> 8132 | I27: 93 | J27: GRAL ACHA | K27: Diputado Nac. | L27: Blanco | M27: 118 | N27: 8584 | Q27: 93 | R27: GRAL ACHA | S27: Gobernador | T27: Comunidad organizada | U27: 683
A28: 27 | B28: EDUARDO CASTEX | C28: Diputado Nac. | D28: PJ | E28: 2488 | G28: 8766 | I28: 27 | J28: EDUARDO CASTEX | K28: Diputado Nac. | L28: PJ | M28: 3101 | O28: 8766 | Q28: 93 | R28: GRAL ACHA | S28: Gobernador | T28: Pueblo Nuevo | U28: 275
A29: 27 | B29: EDUARDO CASTEX | C29: Diputado Nac. | D29: Humanista | E29: 83 | I29: 27 | J29: EDUARDO CASTEX | K29: Diputado Nac. | L29: Humanista | M29: 86 | Q29: 93 | R29: GRAL ACHA | S29: Gobernador | T29: Partido socialista | U29: 118
A30: 27 | B30: EDUARDO CASTEX | C30: Diputado Nac. | D30: Partido de los Trabajadores Soc. | E30: 106 | I30: 27 | J30: EDUARDO CASTEX | K30: Diputado Nac. | L30: Partido de los Trabajadores Soc. | M30: 105 | Q30: 93 | R30: GRAL ACHA | S30: Gobernador | T30: Frente popular pampeano | U30: 77
A31: 27 | B31: EDUARDO CASTEX | C31: Diputado Nac. | D31: FREPAM | E31: 235 | I31: 27 | J31: EDUARDO CASTEX | K31: Diputado Nac. | L31: FREPAM | M31: 89 | Q31: 93 | R31: GRAL ACHA | S31: Gobernador | T31: Nulo | U31: 76
A32: 27 | B32: EDUARDO CASTEX | C32: Diputado Nac. | D32: Izquierda al Frente por el Soc. | E32: 78 | I32: 27 | J32: EDUARDO CASTEX | K32: Diputado Nac. | L32: Izquierda al Frente por el Soc. | M32: 108 | Q32: 93 | R32: GRAL ACHA | S32: Gobernador | T32: Movimiento socialista de los trabajadores | U32: 40
A33: 27 | B33: EDUARDO CASTEX | C33: Diputado Nac. | D33: Cambiemos | E33: 3130 | I33: 27 | J33: EDUARDO CASTEX | K33: Diputado Nac. | L33: Cambiemos | M33: 3052 | Q33: 93 | R33: GRAL ACHA | S33: Gobernador | T33: Desde el pie | U33: 28
A34: 27 | B34: EDUARDO CASTEX | C34: Diputado Nac. | D34: Nulo | E34: 268 | I34: 27 | J34: EDUARDO CASTEX | K34: Diputado Nac. | L34: Nulo | M34: 156 | Q34: 27 | R34: EDUARDO CASTEX | S34: Gobernador | T34: PJ | U34: 2903 | V34: =SUM(U34:U43) -> 6934 | W34: 8731
A35: 27 | B35: EDUARDO CASTEX | C35: Diputado Nac. | D35: Blanco | E35: 117 | F35: =SUM(E28:E35) -> 6505 | I35: 27 | J35: EDUARDO CASTEX | K35: Diputado Nac. | L35: Blanco | M35: 69 | N35: 6766 | Q35: 27 | R35: EDUARDO CASTEX | S35: Gobernador | T35: Cambiemos - FREPAM | U35: 2680
A36: 86 | B36: TOAY | C36: Diputado Nac. | D36: PJ | E36: 3678 | G36: 12268 | I36: 86 | J36: TOAY | K36: Diputado Nac. | L36: PJ | M36: 4385 | O36: 12268 | Q36: 27 | R36: EDUARDO CASTEX | S36: Gobernador | T36: Pueblo Nuevo | U36: 390
A37: 86 | B37: TOAY | C37: Diputado Nac. | D37: Humanista | E37: 252 | I37: 86 | J37: TOAY | K37: Diputado Nac. | L37: Humanista | M37: 206 | Q37: 27 | R37: EDUARDO CASTEX | S37: Gobernador | T37: Partido socialista | U37: 330
A38: 86 | B38: TOAY | C38: Diputado Nac. | D38: Partido de los Trabajadores Soc. | E38: 197 | I38: 86 | J38: TOAY | K38: Diputado Nac. | L38: Partido de los Trabajadores Soc. | M38: 210 | Q38: 27 | R38: EDUARDO CASTEX | S38: Gobernador | T38: Comunidad organizada | U38: 275
A39: 86 | B39: TOAY | C39: Diputado Nac. | D39: FREPAM | E39: 256 | I39: 86 | J39: TOAY | K39: Diputado Nac. | L39: FREPAM | M39: 241 | Q39: 27 | R39: EDUARDO CASTEX | S39: Gobernador | T39: Blanco | U39: 218
A40: 86 | B40: TOAY | C40: Diputado Nac. | D40: Izquierda al Frente por el Soc. | E40: 172 | I40: 86 | J40: TOAY | K40: Diputado Nac. | L40: Izquierda al Frente por el Soc. | M40: 181 | Q40: 27 | R40: EDUARDO CASTEX | S40: Gobernador | T40: Nulo | U40: 78
A41: 86 | B41: TOAY | C41: Diputado Nac. | D41: Cambiemos | E41: 3986 | I41: 86 | J41: TOAY | K41: Diputado Nac. | L41: Cambiemos | M41: 3908 | Q41: 27 | R41: EDUARDO CASTEX | S41: Gobernador | T41: Movimiento socialista de los trabajadores | U41: 26
...

Sheet Resumen
A1: Paso 2017 | H1: PASO 2021 | J1: PASO 2021
A2: Circuito | B2: SANTA ROSA | C2: Categoria | D2: Destino | E2: Cantidad | F2: TOTAL | G2: PADRON | H2: Votos Senadores | I2: Total | J2: Votos Diputados | K2: Total | L2: Padron
A3: 9 y 10 | B3: SANTA ROSA | C3: Diputado Nac. | D3: PJ | E3: 22866 | F3: =+E3+E4+E5+E6 -> 65254 | G3: 90619 | H3: 24519 | I3: =+H3+H4+H5 -> 59058 | J3: 24632 | K3: =+J3+J4+J5 -> 59097 | L3: 93172 | M3: 1
A4: 9 y 10 | B4: SANTA ROSA | C4: Diputado Nac. | D4: Cambiemos | E4: 30769 | H4: 26837 | J4: 26751
A5: 9 y 10 | B5: SANTA ROSA | C5: Diputado Nac. | D5: Otros | E5: =+'Votos por partido'!E5+'Votos por partido'!E6+'Votos por partido'!E7+'Votos por partido'!E8 -> 8313 | H5: 7702 | J5: 7714
A6: 9 y 10 | B6: SANTA ROSA | C6: Diputado Nac. | D6: Nulos y blancos | E6: =+'Votos por partido'!E10+'Votos por partido'!E11 -> 3306
A7: 58 | B7: Gral Pico | C7: Diputado Nac. | D7: PJ | E7: =+'Votos por partido'!E12 -> 11755 | F7: =+E7+E8+E9+E10 -> 37683 | G7: =+'Votos por partido'!G12 -> 50143 | H7: 11694 | I7: =+H7+H8+H9 -> 34455 | J7: 11681 | K7: =+J7+J8+J9 -> 34372 | L7: 51731 | M7: 2
A8: 58 | B8: Gral Pico | C8: Diputado Nac. | D8: Cambiemos | E8: =+'Votos por partido'!E17 -> 18453 | H8: 18739 | J8: 18714
A9: 58 | B9: Gral Pico | C9: Diputado Nac. | D9: Otros | E9: =+'Votos por partido'!E13+'Votos por partido'!E14+'Votos por partido'!E15+'Votos por partido'!E16 -> 5338 | H9: 4022 | J9: 3977
A10: 58 | B10: Gral Pico | C10: Diputado Nac. | D10: Nulos y blancos | E10: =+'Votos por partido'!E18+'Votos por partido'!E19 -> 2137
A11: 93 | B11: Gral Acha | C11: Diputado Nac. | D11: PJ | E11: =+'Votos por partido'!E20 -> 2319 | F11: =+E11+E12+E13+E14 -> 8132 | G11: =+'Votos por partido'!G20 -> 11653 | H11: 2257 | I11: =+H11+H12+H13 -> 7400 | J11: 2253 | K11: =+J11+J12+J13 -> 7676 | L11: 11993 | M11: 3
A12: 93 | B12: Gral Acha | C12: Diputado Nac. | D12: Cambiemos | E12: =+'Votos por partido'!E25 -> 4528 | H12: 4457 | J12: 4733
A13: 93 | B13: Gral Acha | C13: Diputado Nac. | D13: Otros | E13: =+'Votos por partido'!E21+'Votos por partido'!E22+'Votos por partido'!E23+'Votos por partido'!E24 -> 618 | H13: 686 | J13: 690
A14: 93 | B14: Gral Acha | C14: Diputado Nac. | D14: Nulos y blancos | E14: =+'Votos por partido'!E26+'Votos por partido'!E27 -> 667
A15: 27 | B15: E. Castex | C15: Diputado Nac. | D15: PJ | E15: =+'Votos por partido'!E28 -> 2488 | F15: =+E15+E16+E17+E18 -> 6505 | G15: =+'Votos por partido'!G28 -> 8766 | H15: 1944 | I15: =+H15+H16+H17 -> 5599 | J15: 1943 | K15: =+J15+J16+J17 -> 5565 | L15: 8903 | M15: 4
A16: 27 | B16: E. Castex | C16: Diputado Nac. | D16: Cambiemos | E16: =+'Votos por partido'!E33 -> 3130 | H16: 3233 | J16: 3196
A17: 27 | B17: E. Castex | C17: Diputado Nac. | D17: Otros | E17: =+'Votos por partido'!E29+'Votos por partido'!E30+'Votos por partido'!E31+'Votos por partido'!E32 -> 502 | H17: 422 | J17: 426
A18: 27 | B18: E. Castex | C18: Diputado Nac. | D18: Nulos y blancos | E18: =+'Votos por partido'!E34+'Votos por partido'!E35 -> 385
A19: 86 | B19: Toay | C19: Diputado Nac. | D19: PJ | E19: =+'Votos por partido'!E36 -> 3678 | F19: =+E19+E20+E21+E22 -> 8997 | G19: =+'Votos por partido'!G36 -> 12268 | H19: 3586 | I19: =+H19+H20+H21 -> 9000 | J19: 3587 | K19: =+J19+J20+J21 -> 8979 | L19: 14128 | M19: 5
A20: 86 | B20: Toay | C20: Diputado Nac. | D20: Cambiemos | E20: =+'Votos por partido'!E41 -> 3986 | H20: 4355 | J20: 4335
A21: 86 | B21: Toay | C21: Diputado Nac. | D21: Otros | E21: =+'Votos por partido'!E37+'Votos por partido'!E38+'Votos por partido'!E39+'Votos por partido'!E40 -> 877 | H21: 1059 | J21: 1057
A22: 86 | B22: Toay | C22: Diputado Nac. | D22: Nulos y blancos | E22: =+'Votos por partido'!E42+'Votos por partido'!E43 -> 456
A23: 61 | B23: CNIA. 25 DE MAYO | C23: Diputado Nac. | D23: PJ | E23: =+'Votos por partido'!E44 -> 2016 | F23: =E25+E26+E23+E24 -> 5242 | G23: 7373 | H23: =+'2021'!B52 -> 2084 | I23: =SUM(H23:H26) -> 5176 | J23: =+'2021'!D52 -> 2071 | K23: =SUM(J23:J26) -> 5207 | L23: =SUM(L23:L26) -> 0 | M23: 6
A24: 61 | B24: CNIA. 25 DE MAYO | C24: Diputado Nac. | D24: Cambiemos | E24: =+'Votos por partido'!E49 -> 2307 | H24: =+'2021'!B50 -> 2585 | J24: =+'2021'!D50 -> 2600
A25: 61 | B25: CNIA. 25 DE MAYO | C25: Diputado Nac. | D25: Otros | E25: =+'Votos por partido'!E45+'Votos por partido'!E46+'Votos por partido'!E47+'Votos por partido'!E48 -> 507 | H25: =+'2021'!B54 -> 507 | J25: =+'2021'!D54 -> 536
A26: 61 | B26: CNIA. 25 DE MAYO | C26: Diputado Nac. | D26: Nulos y blancos | E26: =+'Votos por partido'!E50+'Votos por partido'!E51 -> 412
A27: 22 | B27: INT. ALVEAR | C27: Diputado Nac. | D27: PJ | E27: =+'Votos por partido'!E52 -> 1706 | F27: =+E27+E28+E29+E30 -> 5375 | G27: 7072 | H27: =+'2021'!B61 -> 2088 | I27: =SUM(H27:H30) -> 4996 | J27: =+'2021'!D61 -> 2114 | K27: =SUM(J27:J30) -> 4740 | L27: =SUM(L27:L30) -> 0 | M27: 7
A28: 22 | B28: INT. ALVEAR | D28: Cambiemos | E28: =+'Votos por partido'!E57 -> 3019 | H28: =+'2021'!B59 -> 2630 | J28: =+'2021'!D59 -> 2626
A29: 22 | B29: INT. ALVEAR | D29: Otros | E29: =+'Votos por partido'!E53+'Votos por partido'!E54+'Votos por partido'!E55+'Votos por partido'!E56 -> 364 | H29: =+'2021'!B63 -> 278
A30: 22 | B30: INT. ALVEAR | D30: Nulos y blancos | E30: =+'Votos por partido'!E58+'Votos por partido'!E59 -> 286
A31: 82 | B31: Realico | D31: PJ | E31: =+'Votos por partido'!E60 -> 1930 | F31: =SUM(E31:E34) -> 5026 | G31: 6960 | H31: =+'2021'!B79 -> 1623 | I31: =SUM(H31:H34) -> 4623 | J31: =+'2021'!D79 -> 1630 | K31: =SUM(J31:J34) -> 4618 | L31: =SUM(L31:L34) -> 0 | M31: 8
A32: 82 | B32: Realico | D32: Cambiemos | E32: =+'Votos por partido'!E65 -> 2386 | H32: =+'2021'!B77 -> 2746 | J32: =+'2021'!D77 -> 2735
A33: 82 | B33: Realico | D33: Otros | E33: =+'Votos por partido'!E61+'Votos por partido'!E62+'Votos por partido'!E63+'Votos por partido'!E64 -> 336 | H33: =+'2021'!B81 -> 254 | J33: =+'2021'!D81 -> 253
A34: 82 | B34: Realico | D34: Nulos y blancos | E34: =+'Votos por partido'!E66+'Votos por partido'!E67 -> 374
A35: 48 | B35: Victorica | D35: PJ | E35: =+'Votos por partido'!E68 -> 1695 | F35: =SUM(E35:E38) -> 3938 | G35: 5433 | H35: =+'2021'!B88 -> 1595 | I35: =SUM(H35:H38) -> 3509 | J35: =+'2021'!D88 -> 1619 | K35: =SUM(J35:J38) -> 3537 | L35: =SUM(L35:L38) -> 0 | M35: 9
A36: 48 | B36: Victorica | D36: Cambiemos | E36: =+'Votos por partido'!E73 -> 1681 | H36: =+'2021'!B86 -> 1590 | J36: =+'2021'!D86 -> 1616
A37: 48 | B37: Victorica | D37: Otros | E37: =+'Votos por partido'!E69+'Votos por partido'!E70+'Votos por partido'!E71+'Votos por partido'!E72 -> 296 | H37: =+'2021'!B90 -> 324 | J37: =+'2021'!D90 -> 302
A38: 48 | B38: Victorica | D38: Nulos y blancos | E38: =+'Votos por partido'!E74+'Votos por partido'!E75 -> 266
A39: 36 | B39: Guatrache | D39: PJ | E39: =+'Votos por partido'!E76 -> 751 | F39: =SUM(E39:E42) -> 2843 | G39: 4249 | H39: =+'2021'!B97 -> 639 | I39: =SUM(H39:H42) -> 2437 | J39: =+'2021'!D97 -> 640 | K39: =SUM(J39:J42) -> 2442 | L39: =SUM(L39:L42) -> 0 | M39: 10
A40: 36 | B40: Guatrache | D40: Cambiemos | E40: =+'Votos por partido'!E81 -> 1718 | H40: =+'2021'!B95 -> 1566 | J40: =+'2021'!D95 -> 1570
...

Sheet 2021
A3: LOCALIDAD: SANTA ROSA
A4: AGRUPACION: | B4: VOTOS SEN | C4: % SEN | D4: VOTOS DIP | E4: % DIP
A5: JUNTOS POR EL CAMBIO | B5: 26837 | C5: 0.454 | D5: 26751 | E5: 0.453
A7: FRENTE DE TODOS | B7: 24519 | C7: 0.415 | D7: 24632 | E7: 0.417
A9: OTROS | B9: 7702 | C9: 0.13 | D9: 7714 | E9: 0.131
A12: LOCALIDAD: GENERAL PICO
A13: AGRUPACION: | B13: VOTOS SEN | C13: %SEN | D13: VOTOS DIP | E13: %DIP
A14: JUNTOS POR EL CAMBIO: | B14: 18739 | C14: 0.544 | D14: 18714 | E14: 0.544
A16: FRENTE DE TODOS: | B16: 11694 | C16: 0.339 | D16: 11681 | E16: 0.34
A18: OTROS: | B18: 4022 | C18: 0.117 | D18: 3977 | E18: 11 ,60%
A21: LOCALIDAD: GENERAL ACHA
A22: AGRUPACION: | B22: VOTOS SEN | C22: %SEN | D22: VOTOS DIP | E22: %DIP
A23: JUNTOS POR EL CAMBIO: | B23: 4457 | C23: 0.602 | D23: 4733 | E23: 0.617
A25: FRENTE DE TODOS: | B25: 2257 | C25: 0.305 | D25: 2253 | E25: 0.294
A27: OTROS: | B27: 686 | C27: 0.092 | D27: 690 | E27: 0.09
A30: LOCALIDAD: TOAY
A31: AGRUPACION: | B31: VOTOS SEN | C31: %SEN | D31: VOTOS DIP | E31: %DIP
A32: JUNTOS POR EL CAMBIO: | B32: 4355 | C32: 0.484 | D32: 4335 | E32: 0.483
A34: FRENTE DE TODOS: | B34: 3586 | C34: 0.398 | D34: 3587 | E34: 0.399
A36: OTROS: | B36: 1059 | C36: 11 ,80% | D36: 1057 | E36: 11 ,80%
A39: LOCALIDAD: EDUARDO CASTEX
A40: AGRUPACION: | B40: VOTOS SEN | C40: %SEN | D40: VOTOS DIP | E40: %DIP
A41: JUNTOS POR EL CAMBIO: | B41: 3233 | C41: 0.577 | D41: 3196 | E41: 0.574
A43: FRENTE DE TODOS: | B43: 1944 | C43: 0.347 | D43: 1943 | E43: 0.349
A45: OTROS: | B45: 422 | C45: 0.075 | D45: 426 | E45: 0.076
A48: LOCALIDAD: 25 DE MAYO
A49: AGRUPACION: | B49: VOTOS SEN | C49: %SEN | D49: VOTOS DIP | E49: %DIP
A50: JUNTOS POR EL CAMBIO: | B50: 2585 | C50: 0.499 | D50: 2600 | E50: 0.499
A52: FRENTE DE TODOS: | B52: 2084 | C52: 0.403 | D52: 2071 | E52: 0.398
A54: OTROS: | B54: 507 | C54: 0.098 | D54: 536 | E54: 0.103
A57: LOCALIDAD: INTENDENTE ALVEAR
A58: AGRUPACION: | B58: VOTOS SEN | C58: %SEN | D58: VOTOS DIP | E58: %DIP
A59: JUNTOS POR EL CAMBIO: | B59: 2630 | C59: 0.526 | D59: 2626 | E59: 0.524
A61: FRENTE DE TODOS: | B61: 2088 | C61: 0.418 | D61: 2114 | E61: 0.422
A63: OTROS: | B63: 278 | C63: 0.054 | D63: 273 | E63: 0.055
A66: LOCALIDAD: INGENIERO LUIGGI
A67: AGRUPACION: | B67: VOTOS SEN | C67: %SEN | D67: VOTOS DIP | E67: %DIP
A68: JUNTOS POR EL CAMBIO: | B68: 1441 | C68: 0.499 | D68: 1443 | E68: 0.498
A70: FRENTE DE TODOS: | B70: 1275 | C70: 0.442 | D70: 1280 | E70: 0.442
A72: OTROS | B72: 171 | C72: 0.059 | D72: 173 | E72: 0.061
...
