Workbook

Sheet 1999-Prov
J3: Categorías | K3: Destino
J4: Intendente | K4: PJ
A5: Circuito | B5: Localidad | C5: Categoria | D5: Destino | E5: Cantidad | F5: TOTAL | G5: TOTAL EMITIDOS S/ ACTA | J5: Concejales | K5: Alianza
A6: 1 | B6: DOBLAS | C6: Intendente | D6: PJ | E6: 480 | F6: =SUM(E6:E8) -> 1237 | G6: 1241 | J6: Juez de Paz | K6: Blanco
A7: 1 | B7: DOBLAS | C7: Intendente | D7: Alianza | E7: 737 | J7: Presidente Comisión de Fomento | K7: Humanista
A8: 1 | B8: DOBLAS | C8: Intendente | D8: Blanco | E8: 20 | J8: Vocales | K8: Acción por la República
A9: 1 | B9: DOBLAS | C9: Concejales | D9: PJ | E9: 454 | F9: =SUM(E9:E11) -> 1227 | K9: Movimiento Federalista Pampeano
A10: 1 | B10: DOBLAS | C10: Concejales | D10: Alianza | E10: 727 | K10: Frente Pueblo Unido - Socialismo Auténtico
A11: 1 | B11: DOBLAS | C11: Concejales | D11: Blanco | E11: 46 | K11: Unión Popular de La Adela
A12: 1 | B12: DOBLAS | C12: Juez de Paz | D12: PJ | E12: 457 | F12: =SUM(E12:E14) -> 1232 | K12: Convocatoria Independiente
A13: 1 | B13: DOBLAS | C13: Juez de Paz | D13: Alianza | E13: 749 | K13: Junta Vecinal de Mauricio Mayer
A14: 1 | B14: DOBLAS | C14: Juez de Paz | D14: Blanco | E14: 26 | K14: Intransigente
A15: 2 | B15: MACACHIN | C15: Intendente | D15: PJ | E15: 1453 | F15: =SUM(E15:E17) -> 3283 | G15: 3288 | K15: Alianza Victorica Electoral y Programática
A16: 2 | B16: MACACHIN | C16: Intendente | D16: Alianza | E16: 1670 | K16: Junta Vecinal de Relmo
A17: 2 | B17: MACACHIN | C17: Intendente | D17: Blanco | E17: 160 | K17: Unidos por Villa Mirasol
A18: 2 | B18: MACACHIN | C18: Concejales | D18: PJ | E18: 1352 | F18: =SUM(E18:E20) -> 3281 | K18: Unión Vecinal Villa Mirasol
A19: 2 | B19: MACACHIN | C19: Concejales | D19: Alianza | E19: 1674 | K19: Unión Vecinal La Maruja
A20: 2 | B20: MACACHIN | C20: Concejales | D20: Blanco | E20: 255 | K20: Unión Vecinal de Pichi Huinca
A21: 2 | B21: MACACHIN | C21: Juez de Paz | D21: PJ | E21: 1325 | F21: =SUM(E21:E23) -> 3283 | K21: Junta Vecinal de A. Van Praet
A22: 2 | B22: MACACHIN | C22: Juez de Paz | D22: Alianza | E22: 1723 | K22: Junta Vecinal de Falucho
A23: 2 | B23: MACACHIN | C23: Juez de Paz | D23: Blanco | E23: 235 | K23: Junta Vecinal Unión por Metileo
A24: 3 | B24: MIGUEL RIGLOS | C24: Intendente | D24: PJ | E24: 531 | F24: =SUM(E24:E26) -> 1655 | G24: 1659
A25: 3 | B25: MIGUEL RIGLOS | C25: Intendente | D25: Alianza | E25: 1080
A26: 3 | B26: MIGUEL RIGLOS | C26: Intendente | D26: Blanco | E26: 44
A27: 3 | B27: MIGUEL RIGLOS | C27: Concejales | D27: PJ | E27: 541 | F27: =SUM(E27:E29) -> 1657
A28: 3 | B28: MIGUEL RIGLOS | C28: Concejales | D28: Alianza | E28: 1041
A29: 3 | B29: MIGUEL RIGLOS | C29: Concejales | D29: Blanco | E29: 75
A30: 3 | B30: MIGUEL RIGLOS | C30: Juez de Paz | D30: PJ | E30: 628 | F30: =SUM(E30:E32) -> 1657
A31: 3 | B31: MIGUEL RIGLOS | C31: Juez de Paz | D31: Alianza | E31: 975
A32: 3 | B32: MIGUEL RIGLOS | C32: Juez de Paz | D32: Blanco | E32: 54
A33: 4 | B33: ROLON | C33: Intendente | D33: PJ | E33: 283 | F33: =SUM(E33:E35) -> 604 | G33: 605
A34: 4 | B34: ROLON | C34: Intendente | D34: Alianza | E34: 298
A35: 4 | B35: ROLON | C35: Intendente | D35: Blanco | E35: 23
A36: 4 | B36: ROLON | C36: Concejales | D36: PJ | E36: 262 | F36: =SUM(E36:E38) -> 604
A37: 4 | B37: ROLON | C37: Concejales | D37: Alianza | E37: 297
A38: 4 | B38: ROLON | C38: Concejales | D38: Blanco | E38: 45
A39: 4 | B39: ROLON | C39: Juez de Paz | D39: PJ | E39: 247 | F39: =SUM(E39:E41) -> 604
A40: 4 | B40: ROLON | C40: Juez de Paz | D40: Alianza | E40: 314
A41: 4 | B41: ROLON | C41: Juez de Paz | D41: Blanco | E41: 43
A42: 5 | B42: TOMAS M DE ANCHORENA | C42: Intendente | D42: PJ | E42: 101 | F42: =SUM(E42:E44) -> 412 | G42: 412
...

Sheet Datos2021
I2: Alianza Victorica Electoral y Programática
A3: ELECCION | B3: CIRCUITO | C3: LOCALIDAD | D3: CATEGORIA | E3: DESTINO | F3: DESTINO 2 | G3: VOTOS | I3: Blanco | J3: 4 - Blanco/Nulo
A4: 2017GRAL | B4: 1 | C4: DOBLAS | D4: Diputado Nac. | E4: PJ | F4: =VLOOKUP(E4,$I$2:$J$30,2,FALSE) -> 1 - PJ | G4: 489 | I4: Cambiemos | J4: 2 - Frepam
A5: 2017GRAL | B5: 1 | C5: DOBLAS | D5: Diputado Nac. | E5: Humanista | F5: =VLOOKUP(E5,$I$2:$J$30,2,FALSE) -> 3 - Otros | G5: 19 | I5: Cambiemos - FREPAM | J5: 2 - Frepam
A6: 2017GRAL | B6: 1 | C6: DOBLAS | D6: Diputado Nac. | E6: Partido de los Trabajadores Soc. | F6: =VLOOKUP(E6,$I$2:$J$30,2,FALSE) -> 3 - Otros | G6: 10 | I6: Compromiso ciudadano | J6: 3 - Otros
A7: 2017GRAL | B7: 1 | C7: DOBLAS | D7: Diputado Nac. | E7: FREPAM | F7: =VLOOKUP(E7,$I$2:$J$30,2,FALSE) -> 2 - Frepam | G7: 19 | I7: Comunidad organizada | J7: 3 - Otros
A8: 2017GRAL | B8: 1 | C8: DOBLAS | D8: Diputado Nac. | E8: Izquierda al Frente por el Soc. | F8: =VLOOKUP(E8,$I$2:$J$30,2,FALSE) -> 3 - Otros | G8: 14 | I8: Desde el pie | J8: 3 - Otros
A9: 2017GRAL | B9: 1 | C9: DOBLAS | D9: Diputado Nac. | E9: Cambiemos | F9: =VLOOKUP(E9,$I$2:$J$30,2,FALSE) -> 2 - Frepam | G9: 548 | I9: Frente justicialista pampeano | J9: 1 - PJ
A10: 2017GRAL | B10: 1 | C10: DOBLAS | D10: Diputado Nac. | E10: Nulo | F10: =VLOOKUP(E10,$I$2:$J$30,2,FALSE) -> 4 - Blanco/Nulo | G10: 44 | I10: Frente popular pampeano | J10: 3 - Otros
A11: 2017GRAL | B11: 1 | C11: DOBLAS | D11: Diputado Nac. | E11: Blanco | F11: =VLOOKUP(E11,$I$2:$J$30,2,FALSE) -> 4 - Blanco/Nulo | G11: 13 | I11: Frente Vecinal Alvearense | J11: 3 - Otros
A12: 2017GRAL | B12: 2 | C12: MACACHIN | D12: Diputado Nac. | E12: PJ | F12: =VLOOKUP(E12,$I$2:$J$30,2,FALSE) -> 1 - PJ | G12: 1806 | I12: FREPAM | J12: 2 - Frepam
A13: 2017GRAL | B13: 2 | C13: MACACHIN | D13: Diputado Nac. | E13: Humanista | F13: =VLOOKUP(E13,$I$2:$J$30,2,FALSE) -> 3 - Otros | G13: 31 | I13: Humanista | J13: 3 - Otros
A14: 2017GRAL | B14: 2 | C14: MACACHIN | D14: Diputado Nac. | E14: Partido de los Trabajadores Soc. | F14: =VLOOKUP(E14,$I$2:$J$30,2,FALSE) -> 3 - Otros | G14: 33 | I14: Izquierda al Frente por el Soc. | J14: 3 - Otros
A15: 2017GRAL | B15: 2 | C15: MACACHIN | D15: Diputado Nac. | E15: FREPAM | F15: =VLOOKUP(E15,$I$2:$J$30,2,FALSE) -> 2 - Frepam | G15: 53 | I15: Junta Vecinal de Falucho | J15: 3 - Otros
... A30: 2017GRAL | B30: 4 | C30: ROLON | D30: Diputado Nac. | E30: Partido de los Trabajadores Soc. | F30: =VLOOKUP(E30,$I$2:$J$30,2,FALSE) -> 3 - Otros | G30: 1 | I30: Cambiemos | J30: 2 - Frepam
A31: 2017GRAL | B31: 4 | C31: ROLON | D31: Diputado Nac. | E31: FREPAM | F31: =VLOOKUP(E31,$I$2:$J$30,2,FALSE) -> 2 - Frepam | G31: 1
A32: 2017GRAL | B32: 4 | C32: ROLON | D32: Diputado Nac. | E32: Izquierda al Frente por el Soc. | F32: =VLOOKUP(E32,$I$2:$J$30,2,FALSE) -> 3 - Otros | G32: 10
A33: 2017GRAL | B33: 4 | C33: ROLON | D33: Diputado Nac. | E33: Cambiemos | F33: =VLOOKUP(E33,$I$2:$J$30,2,FALSE) -> 2 - Frepam | G33: 203
A34: 2017GRAL | B34: 4 | C34: ROLON | D34: Diputado Nac. | E34: Nulo | F34: =VLOOKUP(E34,$I$2:$J$30,2,FALSE) -> 4 - Blanco/Nulo | G34: 4
A35: 2017GRAL | B35: 4 | C35: ROLON | D35: Diputado Nac. | E35: Blanco | F35: =VLOOKUP(E35,$I$2:$J$30,2,FALSE) -> 4 - Blanco/Nulo | G35: 13
A36: 2017GRAL | B36: 5 | C36: TOMAS M DE ANCHORENA | D36: Diputado Nac. | E36: PJ | F36: =VLOOKUP(E36,$I$2:$J$30,2,FALSE) -> 1 - PJ | G36: 119
A37: 2017GRAL | B37: 5 | C37: TOMAS M DE ANCHORENA | D37: Diputado Nac. | E37: Humanista | F37: =VLOOKUP(E37,$I$2:$J$30,2,FALSE) -> 3 - Otros | G37: 1
A38: 2017GRAL | B38: 5 | C38: TOMAS M DE ANCHORENA | D38: Diputado Nac. | E38: Partido de los Trabajadores Soc. | F38: =VLOOKUP(E38,$I$2:$J$30,2,FALSE) -> 3 - Otros | G38: 2
A39: 2017GRAL | B39: 5 | C39: TOMAS M DE ANCHORENA | D39: Diputado Nac. | E39: FREPAM | F39: =VLOOKUP(E39,$I$2:$J$30,2,FALSE) -> 2 - Frepam | G39: 4
A40: 2017GRAL | B40: 5 | C40: TOMAS M DE ANCHORENA | D40: Diputado Nac. | E40: Izquierda al Frente por el Soc. | F40: =VLOOKUP(E40,$I$2:$J$30,2,FALSE) -> 3 - Otros | G40: 1
A41: 2017GRAL | B41: 5 | C41: TOMAS M DE ANCHORENA | D41: Diputado Nac. | E41: Cambiemos | F41: =VLOOKUP(E41,$I$2:$J$30,2,FALSE) -> 2 - Frepam | G41: 175
A42: 2017GRAL | B42: 5 | C42: TOMAS M DE ANCHORENA | D42: Diputado Nac. | E42: Nulo | F42: =VLOOKUP(E42,$I$2:$J$30,2,FALSE) -> 4 - Blanco/Nulo | G42: 1
... A51: 2017GRAL | B51: 6 | C51: ANGUIL | D51: Diputado Nac. | E51: Blanco | F51: =VLOOKUP(E51,$I$2:$J$30,2,FALSE) -> 4 - Blanco/Nulo | G51: 19
A52: 2017GRAL | B52: 9 y 10 | C52: SANTA ROSA | D52: Diputado Nac. | E52: PJ | F52: =VLOOKUP(E52,$I$2:$J$30,2,FALSE) -> 1 - PJ | G52: 29204
A53: 2017GRAL | B53: 9 y 10 | C53: SANTA ROSA | D53: Diputado Nac. | E53: Humanista | F53: =VLOOKUP(E53,$I$2:$J$30,2,FALSE) -> 3 - Otros | G53: 2039
A54: 2017GRAL | B54: 9 y 10 | C54: SANTA ROSA | D54: Diputado Nac. | E54: Partido de los Trabajadores Soc. | F54: =VLOOKUP(E54,$I$2:$J$30,2,FALSE) -> 3 - Otros | G54: 2233
A55: 2017GRAL | B55: 9 y 10 | C55: SANTA ROSA | D55: Diputado Nac. | E55: FREPAM | F55: =VLOOKUP(E55,$I$2:$J$30,2,FALSE) -> 2 - Frepam | G55: 2070
A56: 2017GRAL | B56: 9 y 10 | C56: SANTA ROSA | D56: Diputado Nac. | E56: Izquierda al Frente por el Soc. | F56: =VLOOKUP(E56,$I$2:$J$30,2,FALSE) -> 3 - Otros | G56: 1785
A57: 2017GRAL | B57: 9 y 10 | C57: SANTA ROSA | D57: Diputado Nac. | E57: Cambiemos | F57: =VLOOKUP(E57,$I$2:$J$30,2,FALSE) -> 2 - Frepam | G57: 28917
A58: 2017GRAL | B58: 9 y 10 | C58: SANTA ROSA | D58: Diputado Nac. | E58: Nulo | F58: =VLOOKUP(E58,$I$2:$J$30,2,FALSE) -> 4 - Blanco/Nulo | G58: 1462
A59: 2017GRAL | B59: 9 y 10 | C59: SANTA ROSA | D59: Diputado Nac. | E59: Blanco | F59: =VLOOKUP(E59,$I$2:$J$30,2,FALSE) -> 4 - Blanco/Nulo | G59: 554
A60: 2017GRAL | B60: 11 | C60: LA ADELA | D60: Diputado Nac. | E60: PJ | F60: =VLOOKUP(E60,$I$2:$J$30,2,FALSE) -> 1 - PJ | G60: 884
A61: 2017GRAL | B61: 11 | C61: LA ADELA | D61: Diputado Nac. | E61: Humanista | F61: =VLOOKUP(E61,$I$2:$J$30,2,FALSE) -> 3 - Otros | G61: 25
A62: 2017GRAL | B62: 11 | C62: LA ADELA | D62: Diputado Nac. | E62: Partido de los Trabajadores Soc. | F62: =VLOOKUP(E62,$I$2:$J$30,2,FALSE) -> 3 - Otros | G62: 18
A63: 2017GRAL | B63: 11 | C63: LA ADELA | D63: Diputado Nac. | E63: FREPAM | F63: =VLOOKUP(E63,$I$2:$J$30,2,FALSE) -> 2 - Frepam | G63: 46
...

Sheet 2003-Prov
J3: Categorías | K3: Destino
J4: Intendente | K4: PJ
A5: Circuito | B5: Localidad | C5: Categoria | D5: Destino | E5: Cantidad | F5: TOTAL | G5: TOTAL EMITIDOS S/ ACTA | J5: Concejales | K5: Alianza
A6: 1 | B6: DOBLAS | C6: Intendente | D6: Frente Alternativa Pampeana | E6: 722 | G6: 1246 | J6: Juez de Paz | K6: Blanco
A7: 1 | B7: DOBLAS | C7: Intendente | D7: PJ | E7: 457 | J7: Presidente Comisión de Fomento | K7: Humanista
A8: 1 | B8: DOBLAS | C8: Intendente | D8: Blanco | E8: 65 | F8: =SUM(E6:E8) -> 1244 | J8: Vocales | K8: Acción por la República
A9: 1 | B9: DOBLAS | C9: Concejales | D9: Frente Alternativa Pampeana | E9: 711 | K9: Movimiento Federalista Pampeano
A10: 1 | B10: DOBLAS | C10: Concejales | D10: PJ | E10: 437 | K10: Frente Pueblo Unido - Socialismo Auténtico
A11: 1 | B11: DOBLAS | C11: Concejales | D11: Blanco | E11: 97 | F11: =SUM(E9:E11) -> 1245 | K11: Unión Popular de La Adela
A12: 1 | B12: DOBLAS | C12: Juez de Paz | D12: Frente Alternativa Pampeana | E12: 761 | K12: Convocatoria Independiente
A13: 1 | B13: DOBLAS | C13: Juez de Paz | D13: PJ | E13: 404 | K13: Junta Vecinal de Mauricio Mayer
A14: 1 | B14: DOBLAS | C14: Juez de Paz | D14: Blanco | E14: 81 | F14: =SUM(E12:E14) -> 1246 | K14: Intransigente
A15: 2 | B15: MACACHIN | C15: Intendente | D15: Frente Alternativa Pampeana | E15: 1551 | G15: 3401 | K15: Alianza Victorica Electoral y Programática
A16: 2 | B16: MACACHIN | C16: Intendente | D16: PJ | E16: 1695 | K16: Junta Vecinal de Relmo
A17: 2 | B17: MACACHIN | C17: Intendente | D17: Blanco | E17: 144 | F17: =SUM(E15:E17) -> 3390 | K17: Unidos por Villa Mirasol
A18: 2 | B18: MACACHIN | C18: Concejales | D18: Frente Alternativa Pampeana | E18: 1400 | K18: Unión Vecinal Villa Mirasol
A19: 2 | B19: MACACHIN | C19: Concejales | D19: Alianza Frente Mapa | E19: 203 | K19: Unión Vecinal La Maruja
A20: 2 | B20: MACACHIN | C20: Concejales | D20: PJ | E20: 1679 | K20: Unión Vecinal de Pichi Huinca
A21: 2 | B21: MACACHIN | C21: Concejales | D21: Blanco | E21: 108 | F21: =SUM(E18:E21) -> 3390 | K21: Junta Vecinal de A. Van Praet
A22: 2 | B22: MACACHIN | C22: Juez de Paz | D22: Frente Alternativa Pampeana | E22: 1669 | K22: Junta Vecinal de Falucho
A23: 2 | B23: MACACHIN | C23: Juez de Paz | D23: PJ | E23: 1577 | K23: Junta Vecinal Unión por Metileo
A24: 2 | B24: MACACHIN | C24: Juez de Paz | D24: Blanco | E24: 145 | F24: =SUM(E22:E24) -> 3391 | K24: Frente Alternativa Pampeana
A25: 3 | B25: MIGUEL RIGLOS | C25: Intendente | D25: Frente Alternativa Pampeana | E25: 1025 | G25: 1678 | K25: Frente Popular Anguil
A26: 3 | B26: MIGUEL RIGLOS | C26: Intendente | D26: Alianza FPV | E26: 327 | K26: Alianza Frente Mapa
A27: 3 | B27: MIGUEL RIGLOS | C27: Intendente | D27: PJ | E27: 256 | K27: Alianza FPV
A28: 3 | B28: MIGUEL RIGLOS | C28: Intendente | D28: Blanco | E28: 53 | F28: =SUM(E25:E28) -> 1661 | K28: Alianza Movimiento de Unidad Popular
A29: 3 | B29: MIGUEL RIGLOS | C29: Concejales | D29: Frente Alternativa Pampeana | E29: 1034 | K29: Frente de Integración Pampeana
A30: 3 | B30: MIGUEL RIGLOS | C30: Concejales | D30: Alianza FPV | E30: 273 | K30: Popular de la Reconstrucción
A31: 3 | B31: MIGUEL RIGLOS | C31: Concejales | D31: PJ | E31: 262 | K31: Pueblo Nuevo
A32: 3 | B32: MIGUEL RIGLOS | C32: Concejales | D32: Blanco | E32: 93 | F32: =SUM(E29:E32) -> 1662 | K32: Junta Vecinal por Catriló
A33: 3 | B33: MIGUEL RIGLOS | C33: Juez de Paz | D33: Frente Alternativa Pampeana | E33: 1046 | K33: Junta Vecinal Cambio y Progreso por Lonquimay
A34: 3 | B34: MIGUEL RIGLOS | C34: Juez de Paz | D34: Alianza FPV | E34: 266 | K34: Afirmación para una República Igualitaria
A35: 3 | B35: MIGUEL RIGLOS | C35: Juez de Paz | D35: PJ | E35: 280 | K35: Movimiento de Integración y Desarrollo
A36: 3 | B36: MIGUEL RIGLOS | C36: Juez de Paz | D36: Blanco | E36: 79 | F36: =SUM(E33:E36) -> 1671 | K36: Unión por el Trabajo y el Progreso de Santa Isabel
A37: 4 | B37: ROLON | C37: Intendente | D37: Frente Alternativa Pampeana | E37: 212 | G37: 558 | K37: Frente para el Cambio de Larroude
A38: 4 | B38: ROLON | C38: Intendente | D38: PJ | E38: 326 | K38: Frente Todos por Ceballos
A39: 4 | B39: ROLON | C39: Intendente | D39: Blanco | E39: 20 | F39: =SUM(E37:E39) -> 558 | K39: Frente Vecinal Alvearense
A40: 4 | B40: ROLON | C40: Concejales | D40: Frente Alternativa Pampeana | E40: 215 | K40: Frente Unión por Algarrobo del Aguila
A41: 4 | B41: ROLON | C41: Concejales | D41: PJ | E41: 319 | K41: Frente Unión por La Humada
A42: 4 | B42: ROLON | C42: Concejales | D42: Blanco | E42: 24 | F42: =SUM(E40:E42) -> 558 | K42: Frente Integrador por E. Castex
...

Sheet Elecciones
A3: Id | B3: EleccionId | C3: LocalidadId | D3: NroElectores | E3: TotalPadron
A4: 1 | B4: PRES2013 | C4: 74 | D4: =31347+35363 -> 66710 | E4: =40547+44849 -> 85396 | F4: =D4/E4 -> 0.78118413 | J4: 00GRAL1999
A5: 2 | B5: PRES2013 | C5: 35 | D5: =22169+14858 -> 37027 | E5: =18647+28080 -> 46727 | F5: =D5/E5 -> 0.79241124 | J5: 01GRAL2003
A6: 3 | B6: PRES2013 | C6: 37 | D6: 8338 | E6: 10855 | F6: =D6/E6 -> 0.76812529 | J6: PRES1999
A7: 4 | B7: PRES2013 | C7: 78 | D7: 7255 | E7: 9128 | F7: =D7/E7 -> 0.79480719 | J7: PRES2003
A8: 5 | B8: PRES2013 | C8: 32 | D8: 6729 | E8: 8426 | F8: =D8/E8 -> 0.79859957 | J8: PRES2011
A9: 6 | B9: PRES2013 | C9: 19 | D9: 5140 | E9: 6365 | F9: =D9/E9 -> 0.80754124 | J9: PRES2013
A10: 7 | B10: PRES2013 | C10: 43 | D10: 5296 | E10: 6508 | F10: =D10/E10 -> 0.81376767 | J10: PRES2015
A11: 8 | B11: PRES2013 | C11: 71 | D11: 5120 | E11: 6433 | F11: =D11/E11 -> 0.79589616 | J11: PRIM2017
A12: 9 | B12: PRES2013 | C12: 86 | D12: 4224 | E12: 5167 | F12: =D12/E12 -> 0.81749565
A13: 10 | B13: PRES2013 | C13: 40 | D13: 2902 | E13: 3907 | F13: =D13/E13 -> 0.74276939
A14: 11 | B14: PRES2013 | C14: 53 | D14: 3625 | E14: 4313 | F14: =D14/E14 -> 0.84048226
A15: 12 | B15: PRES2013 | C15: 42 | D15: 3230 | E15: 4024 | F15: =D15/E15 -> 0.8026839
A16: 13 | B16: PRES2013 | C16: 15 | D16: 2743 | E16: 3357 | F16: =D16/E16 -> 0.8170986
A17: 14 | B17: PRES2013 | C17: 68 | D17: 2539 | E17: 3232 | F17: =D17/E17 -> 0.78558168
A18: 15 | B18: PRES2015 | C18: 74 | D18: =37277+32774 -> 70051 | E18: =41964+46707 -> 88671 | F18: =D18/E18 -> 0.79001026
A19: 16 | B19: PRES2015 | C19: 35 | D19: =22998+16719 -> 39717 | E19: =20334+28408 -> 48742 | F19: =D19/E19 -> 0.81484141
A20: 17 | B20: PRES2015 | C20: 37 | D20: 8835 | E20: 11322 | F20: =D20/E20 -> 0.78033916
A21: 18 | B21: PRES2015 | C21: 78 | D21: 8750 | E21: 10863 | F21: =D21/E21 -> 0.80548651
A22: 19 | B22: PRES2015 | C22: 32 | D22: 7197 | E22: 8639 | F22: =D22/E22 -> 0.83308253
A23: 20 | B23: PRES2015 | C23: 19 | D23: 5914 | E23: 6941 | F23: =D23/E23 -> 0.85203861
A24: 21 | B24: PRES2015 | C24: 43 | D24: 5823 | E24: 6804 | F24: =D24/E24 -> 0.85582011
A25: 22 | B25: PRES2015 | C25: 71 | D25: 5544 | E25: 6728 | F25: =D25/E25 -> 0.82401902
A26: 23 | B26: PRES2015 | C26: 86 | D26: 4603 | E26: 5329 | F26: =D26/E26 -> 0.86376431
A27: 24 | B27: PRES2015 | C27: 40 | D27: 3082 | E27: 4090 | F27: =D27/E27 -> 0.75354523
A28: 25 | B28: PRES2015 | C28: 53 | D28: 3866 | E28: 4526 | F28: =D28/E28 -> 0.85417587
A29: 26 | B29: PRES2015 | C29: 42 | D29: 3445 | E29: 4158 | F29: =D29/E29 -> 0.82852333
A30: 27 | B30: PRES2015 | C30: 15 | D30: 3134 | E30: 3640 | F30: =D30/E30 -> 0.86098901
A31: 28 | B31: PRES2015 | C31: 68 | D31: 2795 | E31: 3351 | F31: =D31/E31 -> 0.83407938
A32: 29 | B32: PRIM2017 | C32: 74 | D32: =35177+30077 -> 65254 | E32: =42539+48080 -> 90619 | F32: =D32/E32 -> 0.72009181
A33: 30 | B33: PRIM2017 | C33: 35 | D33: =21316+16367 -> 37683 | E33: =21562+28581 -> 50143 | F33: =D33/E33 -> 0.75151068
A34: 31 | B34: PRIM2017 | C34: 37 | D34: 8132 | E34: 11653 | F34: =D34/E34 -> 0.69784605
A35: 32 | B35: PRIM2017 | C35: 78 | D35: 8997 | E35: 12268 | F35: =D35/E35 -> 0.73337137
A36: 33 | B36: PRIM2017 | C36: 32 | D36: 6505 | E36: 8766 | F36: =D36/E36 -> 0.74207164
A37: 34 | B37: PRIM2017 | C37: 19 | D37: 5242 | E37: 7373 | F37: =D37/E37 -> 0.71097247
A38: 35 | B38: PRIM2017 | C38: 43 | D38: 5375 | E38: 7072 | F38: =D38/E38 -> 0.76003959
A39: 36 | B39: PRIM2017 | C39: 71 | D39: 5026 | E39: 6960 | F39: =D39/E39 -> 0.72212644
A40: 37 | B40: PRIM2017 | C40: 86 | D40: 3938 | E40: 5433 | F40: =D40/E40 -> 0.72482974
A41: 38 | B41: PRIM2017 | C41: 40 | D41: 2843 | E41: 4249 | F41: =D41/E41 -> 0.66909861
A42: 39 | B42: PRIM2017 | C42: 53 | D42: 3666 | E42: 4555 | F42: =D42/E42 -> 0.80482986
...

Sheet 2011-Prov
I3: Categorías | J3: Destino
I4: Intendente | J4: PJ
A5: Circuito | B5: Localidad | C5: Intendente | D5: Destino | E5: Cantidad | F5: TOTAL | I5: Concejales | J5: Alianza
A6: 1 | B6: DOBLAS | C6: Intendente | D6: PJ | E6: 484 | I6: Juez de Paz | J6: Blanco
A7: 1 | B7: DOBLAS | C7: Intendente | D7: FREPAM | E7: 330 | I7: Presidente Comisión de Fomento | J7: Humanista
A8: 1 | B8: DOBLAS | C8: Intendente | D8: Frente para la comunidad organizada | E8: 390 | I8: Gobernador | J8: Acción por la República
A9: 1 | B9: DOBLAS | C9: Intendente | D9: Blanco | E9: 56 | F9: =SUM(E6:E9) -> 1260 | I9: Vocales | J9: Movimiento Federalista Pampeano
A10: 1 | B10: DOBLAS | C10: Concejales | D10: PJ | E10: 427 | I10: Diputados Provinciales | J10: Socialismo Auténtico
A11: 1 | B11: DOBLAS | C11: Concejales | D11: FREPAM | E11: 384 | J11: Frente Pueblo Unido - Socialismo Auténtico
A12: 1 | B12: DOBLAS | C12: Concejales | D12: Frente para la comunidad organizada | E12: 352 | J12: Unión Popular de La Adela
A13: 1 | B13: DOBLAS | C13: Concejales | D13: Blanco | E13: 97 | F13: =SUM(E10:E13) -> 1260 | J13: Convocatoria Independiente
A14: 1 | B14: DOBLAS | C14: Juez de Paz | D14: PJ | E14: 432 | J14: Patria Grande
A15: 1 | B15: DOBLAS | C15: Juez de Paz | D15: FREPAM | E15: 322 | J15: Alianza Unión por Santa Isabel
A16: 1 | B16: DOBLAS | C16: Juez de Paz | D16: Frente para la comunidad organizada | E16: 387 | J16: Junta Vecinal de Mauricio Mayer
A17: 1 | B17: DOBLAS | C17: Juez de Paz | D17: Blanco | E17: 120 | F17: =SUM(E14:E17) -> 1261 | J17: Intransigente
A18: 2 | B18: MACACHIN | C18: Intendente | D18: PJ | E18: 1840 | J18: Alianza Victorica Electoral y Programática
A19: 2 | B19: MACACHIN | C19: Intendente | D19: FREPAM | E19: 1356 | J19: Junta vecinal por y para Ceballos
A20: 2 | B20: MACACHIN | C20: Intendente | D20: Frente para la comunidad organizada | E20: 225 | J20: Junta Vecinal de Relmo
A21: 2 | B21: MACACHIN | C21: Intendente | D21: Blanco | E21: 189 | F21: =SUM(E18:E21) -> 3610 | J21: Unidos por Villa Mirasol
A22: 2 | B22: MACACHIN | C22: Concejales | D22: PJ | E22: 1774 | J22: Unión Vecinal Villa Mirasol
A23: 2 | B23: MACACHIN | C23: Concejales | D23: FREPAM | E23: 1293 | J23: Junta Vecinal por Arauz
A24: 2 | B24: MACACHIN | C24: Concejales | D24: Frente para la comunidad organizada | E24: 292 | J24: Movimiento Popular Veinticinqueño Juntos por 25
A25: 2 | B25: MACACHIN | C25: Concejales | D25: Blanco | E25: 251 | F25: =SUM(E22:E25) -> 3610 | J25: Unión Vecinal La Maruja
A26: 2 | B26: MACACHIN | C26: Juez de Paz | D26: PJ | E26: 1670 | J26: Unión Vecinal de Pichi Huinca
A27: 2 | B27: MACACHIN | C27: Juez de Paz | D27: FREPAM | E27: 1581 | J27: Junta Vecinal de A. Van Praet
A28: 2 | B28: MACACHIN | C28: Juez de Paz | D28: Blanco | E28: 361 | F28: =SUM(E26:E28) -> 3612 | J28: Junta Vecinal de Falucho
A29: 3 | B29: MIGUEL RIGLOS | C29: Intendente | D29: PJ | E29: 935 | J29: Junta Vecinal Quetrequén Somos Todos
A30: 3 | B30: MIGUEL RIGLOS | C30: Intendente | D30: FREPAM | E30: 799 | J30: Junta Vecinal Unión por Metileo
A31: 3 | B31: MIGUEL RIGLOS | C31: Intendente | D31: Blanco | E31: 34 | F31: =SUM(E29:E31) -> 1768 | J31: Frente Alternativa Pampeana
A32: 3 | B32: MIGUEL RIGLOS | C32: Concejales | D32: PJ | E32: 855 | J32: Frente Popular Anguil
A33: 3 | B33: MIGUEL RIGLOS | C33: Concejales | D33: FREPAM | E33: 849 | J33: Unidad 25
A34: 3 | B34: MIGUEL RIGLOS | C34: Concejales | D34: Blanco | E34: 63 | F34: =SUM(E32:E34) -> 1767 | J34: Alianza Frente Mapa
A35: 3 | B35: MIGUEL RIGLOS | C35: Juez de Paz | D35: PJ | E35: 879 | J35: Alianza FPV
A36: 3 | B36: MIGUEL RIGLOS | C36: Juez de Paz | D36: FREPAM | E36: 817 | J36: Alianza Movimiento de Unidad Popular
A37: 3 | B37: MIGUEL RIGLOS | C37: Juez de Paz | D37: Blanco | E37: 69 | F37: =SUM(E35:E37) -> 1765 | J37: Frente de Integración Pampeana
A38: 4 | B38: ROLON | C38: Intendente | D38: PJ | E38: 283 | J38: Popular de la Reconstrucción
A39: 4 | B39: ROLON | C39: Intendente | D39: FREPAM | E39: 200 | J39: Pueblo Nuevo
A40: 4 | B40: ROLON | C40: Intendente | D40: Blanco | E40: 24 | F40: =SUM(E38:E40) -> 507 | J40: Junta Vecinal por Catriló
A41: 4 | B41: ROLON | C41: Concejales | D41: PJ | E41: 288 | J41: Junta Vecinal Cambio y Progreso por Lonquimay
A42: 4 | B42: ROLON | C42: Concejales | D42: FREPAM | E42: 177 | J42: Afirmación para una República Igualitaria
...

Sheet 2011 gral Dip
A3: Circuito | B3: Localidad | C3: Categoria | D3: Destino | F3: TOTAL | G3: PADRON | J3: Categorías | K3: Destino
A4: 1 | B4: DOBLAS | C4: Diputado Nac. | D4: Movimiento de Integración y Desarrollo | E4: 6 | J4: Intendente | K4: PJ
A5: 1 | B5: DOBLAS | C5: Diputado Nac. | D5: Humanista | E5: 488 | J5: Concejales | K5: Alianza
A6: 1 | B6: DOBLAS | C6: Diputado Nac. | D6: Coalición Cívica ARI | E6: 17 | J6: Juez de Paz | K6: Blanco
A7: 1 | B7: DOBLAS | C7: Diputado Nac. | D7: Alianza Compromiso Federal | E7: 30 | J7: Presidente Comisión de Fomento | K7: Humanista
A8: 1 | B8: DOBLAS | C8: Diputado Nac. | D8: FREPAM | E8: 388 | J8: Vocales | K8: Acción por la República
A9: 1 | B9: DOBLAS | C9: Diputado Nac. | D9: Blanco | E9: 329 | J9: Presidente | K9: Movimiento Federalista Pampeano
A10: 1 | B10: DOBLAS | C10: Diputado Nac. | D10: Nulo | E10: 7 | F10: =SUM(E4:E10) -> 1265 | J10: Senador Nac. | K10: Socialismo Auténtico
A11: 2 | B11: MACACHIN | C11: Diputado Nac. | D11: Movimiento de Integración y Desarrollo | E11: 53 | J11: Diputado Nac. | K11: Frente Pueblo Unido - Socialismo Auténtico
A12: 2 | B12: MACACHIN | C12: Diputado Nac. | D12: Humanista | E12: 1705 | K12: Unión Popular de La Adela
A13: 2 | B13: MACACHIN | C13: Diputado Nac. | D13: Coalición Cívica ARI | E13: 19 | K13: Convocatoria Independiente
A14: 2 | B14: MACACHIN | C14: Diputado Nac. | D14: Alianza Compromiso Federal | E14: 46 | K14: Patria Grande
A15: 2 | B15: MACACHIN | C15: Diputado Nac. | D15: FREPAM | E15: 1314 | K15: Alianza Unión por Santa Isabel
A16: 2 | B16: MACACHIN | C16: Diputado Nac. | D16: Blanco | E16: 467 | K16: Junta Vecinal de Mauricio Mayer
A17: 2 | B17: MACACHIN | C17: Diputado Nac. | D17: Nulo | E17: 14 | F17: =SUM(E11:E17) -> 3618 | K17: Intransigente
A18: 3 | B18: MIGUEL RIGLOS | C18: Diputado Nac. | D18: Movimiento de Integración y Desarrollo | E18: 4 | K18: Alianza Victorica Electoral y Programática
A19: 3 | B19: MIGUEL RIGLOS | C19: Diputado Nac. | D19: Humanista | E19: 745 | K19: Junta vecinal por y para Ceballos
A20: 3 | B20: MIGUEL RIGLOS | C20: Diputado Nac. | D20: Coalición Cívica ARI | E20: 3 | K20: Junta Vecinal de Relmo
A21: 3 | B21: MIGUEL RIGLOS | C21: Diputado Nac. | D21: Alianza Compromiso Federal | E21: 14 | K21: Unidos por Villa Mirasol
A22: 3 | B22: MIGUEL RIGLOS | C22: Diputado Nac. | D22: FREPAM | E22: 848 | K22: Unión Vecinal Villa Mirasol
A23: 3 | B23: MIGUEL RIGLOS | C23: Diputado Nac. | D23: Blanco | E23: 138 | K23: Junta Vecinal por Arauz
A24: 3 | B24: MIGUEL RIGLOS | C24: Diputado Nac. | D24: Nulo | E24: 13 | F24: =SUM(E18:E24) -> 1765 | K24: Movimiento Popular Veinticinqueño Juntos por 25
A25: 4 | B25: ROLON | C25: Diputado Nac. | D25: Movimiento de Integración y Desarrollo | E25: 3 | K25: Unión Vecinal La Maruja
A26: 4 | B26: ROLON | C26: Diputado Nac. | D26: Humanista | E26: 246 | K26: Unión Vecinal de Pichi Huinca
A27: 4 | B27: ROLON | C27: Diputado Nac. | D27: Coalición Cívica ARI | E27: 2 | K27: Junta Vecinal de A. Van Praet
A28: 4 | B28: ROLON | C28: Diputado Nac. | D28: Alianza Compromiso Federal | E28: 8 | K28: Junta Vecinal de Falucho
A29: 4 | B29: ROLON | C29: Diputado Nac. | D29: FREPAM | E29: 168 | K29: Junta Vecinal Quetrequén Somos Todos
A30: 4 | B30: ROLON | C30: Diputado Nac. | D30: Blanco | E30: 80 | K30: Junta Vecinal Unión por Metileo
A31: 4 | B31: ROLON | C31: Diputado Nac. | D31: Nulo | E31: 0 | F31: =SUM(E25:E31) -> 507 | K31: Frente Alternativa Pampeana
A32: 5 | B32: TOMAS M DE ANCHORENA | C32: Diputado Nac. | D32: Movimiento de Integración y Desarrollo | E32: 7 | K32: Frente Popular Anguil
A33: 5 | B33: TOMAS M DE ANCHORENA | C33: Diputado Nac. | D33: Humanista | E33: 33 | K33: Unidad 25
A34: 5 | B34: TOMAS M DE ANCHORENA | C34: Diputado Nac. | D34: Coalición Cívica ARI | E34: 8 | K34: Alianza Frente Mapa
A35: 5 | B35: TOMAS M DE ANCHORENA | C35: Diputado Nac. | D35: Alianza Compromiso Federal | E35: 16 | K35: Alianza FPV
A36: 5 | B36: TOMAS M DE ANCHORENA | C36: Diputado Nac. | D36: FREPAM | E36: 192 | K36: Alianza Movimiento de Unidad Popular
A37: 5 | B37: TOMAS M DE ANCHORENA | C37: Diputado Nac. | D37: Blanco | E37: 74 | K37: Frente de Integración Pampeana
A38: 5 | B38: TOMAS M DE ANCHORENA | C38: Diputado Nac. | D38: Nulo | E38: 6 | F38: =SUM(E32:E38) -> 336 | K38: Popular de la Reconstrucción
A39: 6 | B39: ANGUIL | C39: Diputado Nac. | D39: Movimiento de Integración y Desarrollo | E39: 4 | K39: Pueblo Nuevo
A40: 6 | B40: ANGUIL | C40: Diputado Nac. | D40: Humanista | E40: 612 | K40: Junta Vecinal por Catriló
A41: 6 | B41: ANGUIL | C41: Diputado Nac. | D41: Coalición Cívica ARI | E41: 6 | K41: Junta Vecinal Cambio y Progreso por Lonquimay
A42: 6 | B42: ANGUIL | C42: Diputado Nac. | D42: Alianza Compromiso Federal | E42: 20 | K42: Afirmación para una República Igualitaria
...

Sheet 2011Gral Pres.
A2: Circuito | B2: Localidad | C2: Categoría | D2: Destino | E2: Cantidad | F2: Total
A3: 1 | B3: DOBLAS | C3: Presidente | D3: Coalición Cívica ARI | E3: 15 | H3: Categorías | I3: Destino
A4: 1 | B4: DOBLAS | C4: Presidente | D4: Alianza FPV | E4: 606 | H4: Intendente | I4: PJ
A5: 1 | B5: DOBLAS | C5: Presidente | D5: Frente Popular | E5: 40 | H5: Concejales | I5: Alianza
A6: 1 | B6: DOBLAS | C6: Presidente | D6: Alianza Compromiso Federal | E6: 71 | H6: Juez de Paz | I6: Blanco
A7: 1 | B7: DOBLAS | C7: Presidente | D7: Frente Amplio Progresista | E7: 157 | H7: Presidente Comisión de Fomento | I7: Humanista
A8: 1 | B8: DOBLAS | C8: Presidente | D8: Frente de Izquierda y de los Trabajadores | E8: 8 | H8: Vocales | I8: Acción por la República
A9: 1 | B9: DOBLAS | C9: Presidente | D9: Unión para el Desarrollo Social | E9: 169 | H9: Presidente | I9: Movimiento Federalista Pampeano
A10: 1 | B10: DOBLAS | C10: Presidente | D10: Blanco | E10: 198 | H10: Senador Nac. | I10: Socialismo Auténtico
A11: 1 | B11: DOBLAS | C11: Presidente | D11: Nulo | E11: 1 | F11: =SUM(E3:E11) -> 1265 | I11: Coalición
A12: 2 | B12: MACACHIN | C12: Presidente | D12: Coalición Cívica ARI | E12: 27 | H12: Diputado Nac. | I12: Frente Pueblo Unido - Socialismo Auténtico
A13: 2 | B13: MACACHIN | C13: Presidente | D13: Alianza FPV | E13: 1805 | I13: Unión Popular de La Adela
A14: 2 | B14: MACACHIN | C14: Presidente | D14: Frente Popular | E14: 272 | I14: Convocatoria Independiente
A15: 2 | B15: MACACHIN | C15: Presidente | D15: Alianza Compromiso Federal | E15: 164 | I15: Patria Grande
A16: 2 | B16: MACACHIN | C16: Presidente | D16: Frente Amplio Progresista | E16: 291 | I16: Alianza Unión por Santa Isabel
A17: 2 | B17: MACACHIN | C17: Presidente | D17: Frente de Izquierda y de los Trabajadores | E17: 23 | I17: Junta Vecinal de Mauricio Mayer
A18: 2 | B18: MACACHIN | C18: Presidente | D18: Unión para el Desarrollo Social | E18: 590 | I18: Intransigente
A19: 2 | B19: MACACHIN | C19: Presidente | D19: Blanco | E19: 431 | I19: Alianza Victorica Electoral y Programática
A20: 2 | B20: MACACHIN | C20: Presidente | D20: Nulo | E20: 15 | F20: =SUM(E12:E20) -> 3618 | I20: Coalición Cívica ARI
A21: 3 | B21: MIGUEL RIGLOS | C21: Presidente | D21: Coalición Cívica ARI | E21: 7 | I21: Junta vecinal por y para Ceballos
A22: 3 | B22: MIGUEL RIGLOS | C22: Presidente | D22: Alianza FPV | E22: 782 | I22: Junta Vecinal de Relmo
A23: 3 | B23: MIGUEL RIGLOS | C23: Presidente | D23: Frente Popular | E23: 32 | I23: Unidos por Villa Mirasol
A24: 3 | B24: MIGUEL RIGLOS | C24: Presidente | D24: Alianza Compromiso Federal | E24: 79 | I24: Unión Vecinal Villa Mirasol
A25: 3 | B25: MIGUEL RIGLOS | C25: Presidente | D25: Frente Amplio Progresista | E25: 135 | I25: Junta Vecinal por Arauz
A26: 3 | B26: MIGUEL RIGLOS | C26: Presidente | D26: Frente de Izquierda y de los Trabajadores | E26: 9 | I26: Movimiento Popular Veinticinqueño Juntos por 25
A27: 3 | B27: MIGUEL RIGLOS | C27: Presidente | D27: Unión para el Desarrollo Social | E27: 439 | I27: Unión Vecinal La Maruja
A28: 3 | B28: MIGUEL RIGLOS | C28: Presidente | D28: Blanco | E28: 275 | I28: Unión Vecinal de Pichi Huinca
A29: 3 | B29: MIGUEL RIGLOS | C29: Presidente | D29: Nulo | E29: 7 | F29: =SUM(E21:E29) -> 1765 | I29: Frente Popular
A30: 4 | B30: ROLON | C30: Presidente | D30: Coalición Cívica ARI | E30: 2 | I30: Junta Vecinal de A. Van Praet
A31: 4 | B31: ROLON | C31: Presidente | D31: Alianza FPV | E31: 273 | I31: Junta Vecinal de Falucho
A32: 4 | B32: ROLON | C32: Presidente | D32: Frente Popular | E32: 14 | I32: Junta Vecinal Quetrequén Somos Todos
A33: 4 | B33: ROLON | C33: Presidente | D33: Alianza Compromiso Federal | E33: 14 | I33: Junta Vecinal Unión por Metileo
A34: 4 | B34: ROLON | C34: Presidente | D34: Frente Amplio Progresista | E34: 38 | I34: Frente Alternativa Pampeana
A35: 4 | B35: ROLON | C35: Presidente | D35: Frente de Izquierda y de los Trabajadores | E35: 7 | I35: Frente Popular Anguil
A36: 4 | B36: ROLON | C36: Presidente | D36: Unión para el Desarrollo Social | E36: 69 | I36: Unidad 25
A37: 4 | B37: ROLON | C37: Presidente | D37: Blanco | E37: 87 | I37: Alianza Frente Mapa
A38: 4 | B38: ROLON | C38: Presidente | D38: Nulo | E38: 3 | F38: =SUM(E30:E38) -> 507 | I38: Frente Amplio Progresista
A39: 5 | B39: TOMAS M DE ANCHORENA | C39: Presidente | D39: Coalición Cívica ARI | E39: 7 | I39: Alianza FPV
A40: 5 | B40: TOMAS M DE ANCHORENA | C40: Presidente | D40: Alianza FPV | E40: 74 | I40: Alianza Movimiento de Unidad Popular
A41: 5 | B41: TOMAS M DE ANCHORENA | C41: Presidente | D41: Frente Popular | E41: 20 | I41: Frente de Integración Pampeana
...

Sheet 2013Gral
I3: Categorías | J3: Destino
I4: Intendente | J4: PJ
A5: Circuito | B5: Localidad | C5: Categoria | D5: Destino | E5: Cantidad | F5: TOTAL | G5: PADRON | I5: Concejales | J5: Alianza
A6: 1 | B6: DOBLAS | C6: Diputado Nac. | D6: PJ | E6: 447 | G6: 1464 | I6: Juez de Paz | J6: Blanco
A7: 1 | B7: DOBLAS | C7: Diputado Nac. | D7: Humanista | E7: 32 | I7: Presidente Comisión de Fomento | J7: Humanista
A8: 1 | B8: DOBLAS | C8: Diputado Nac. | D8: Pueblo Nuevo | E8: 22 | I8: Vocales | J8: Acción por la República
A9: 1 | B9: DOBLAS | C9: Diputado Nac. | D9: Partido de los Trabajadores Soc. | E9: 13 | I9: Presidente | J9: Movimiento Federalista Pampeano
A10: 1 | B10: DOBLAS | C10: Diputado Nac. | D10: FREPAM | E10: 388 | I10: Senador Nac. | J10: Socialismo Auténtico
A11: 1 | B11: DOBLAS | C11: Diputado Nac. | D11: Frente Propuesta Federal | E11: 245 | I11: Diputado Nac. | J11: Frente Pueblo Unido - Socialismo Auténtico
A12: 1 | B12: DOBLAS | C12: Diputado Nac. | D12: Blanco | E12: 11 | J12: Unión Popular de La Adela
A13: 1 | B13: DOBLAS | C13: Diputado Nac. | D13: Nulo | E13: 34 | F13: =SUM(E6:E13) -> 1192 | J13: Convocatoria Independiente
A14: 2 | B14: MACACHIN | C14: Diputado Nac. | D14: PJ | E14: 1802 | G14: 4313 | J14: Patria Grande
A15: 2 | B15: MACACHIN | C15: Diputado Nac. | D15: Humanista | E15: 98 | J15: Alianza Unión por Santa Isabel
A16: 2 | B16: MACACHIN | C16: Diputado Nac. | D16: Pueblo Nuevo | E16: 70 | J16: Junta Vecinal de Mauricio Mayer
A17: 2 | B17: MACACHIN | C17: Diputado Nac. | D17: Partido de los Trabajadores Soc. | E17: 38 | J17: Intransigente
A18: 2 | B18: MACACHIN | C18: Diputado Nac. | D18: FREPAM | E18: 1232 | J18: Alianza Victorica Electoral y Programática
A19: 2 | B19: MACACHIN | C19: Diputado Nac. | D19: Frente Propuesta Federal | E19: 315 | J19: Junta vecinal por y para Ceballos
A20: 2 | B20: MACACHIN | C20: Diputado Nac. | D20: Blanco | E20: 31 | J20: Junta Vecinal de Relmo
A21: 2 | B21: MACACHIN | C21: Diputado Nac. | D21: Nulo | E21: 39 | F21: =SUM(E14:E21) -> 3625 | J21: Unidos por Villa Mirasol
A22: 3 | B22: MIGUEL RIGLOS | C22: Diputado Nac. | D22: PJ | E22: 859 | G22: 2039 | J22: Unión Vecinal Villa Mirasol
A23: 3 | B23: MIGUEL RIGLOS | C23: Diputado Nac. | D23: Humanista | E23: 24 | J23: Junta Vecinal por Arauz
A24: 3 | B24: MIGUEL RIGLOS | C24: Diputado Nac. | D24: Pueblo Nuevo | E24: 34 | J24: Movimiento Popular Veinticinqueño Juntos por 25
A25: 3 | B25: MIGUEL RIGLOS | C25: Diputado Nac. | D25: Partido de los Trabajadores Soc. | E25: 18 | J25: Unión Vecinal La Maruja
A26: 3 | B26: MIGUEL RIGLOS | C26: Diputado Nac. | D26: FREPAM | E26: 628 | J26: Unión Vecinal de Pichi Huinca
A27: 3 | B27: MIGUEL RIGLOS | C27: Diputado Nac. | D27: Frente Propuesta Federal | E27: 78 | J27: Junta Vecinal de A. Van Praet
A28: 3 | B28: MIGUEL RIGLOS | C28: Diputado Nac. | D28: Blanco | E28: 23 | J28: Junta Vecinal de Falucho
A29: 3 | B29: MIGUEL RIGLOS | C29: Diputado Nac. | D29: Nulo | E29: 17 | F29: =SUM(E22:E29) -> 1681 | J29: Junta Vecinal Quetrequén Somos Todos
A30: 4 | B30: ROLON | C30: Diputado Nac. | D30: PJ | E30: 248 | G30: 598 | J30: Junta Vecinal Unión por Metileo
A31: 4 | B31: ROLON | C31: Diputado Nac. | D31: Humanista | E31: 19 | J31: Frente Alternativa Pampeana
A32: 4 | B32: ROLON | C32: Diputado Nac. | D32: Pueblo Nuevo | E32: 14 | J32: Frente Popular Anguil
A33: 4 | B33: ROLON | C33: Diputado Nac. | D33: Partido de los Trabajadores Soc. | E33: 7 | J33: Unidad 25
A34: 4 | B34: ROLON | C34: Diputado Nac. | D34: FREPAM | E34: 128 | J34: Alianza Frente Mapa
A35: 4 | B35: ROLON | C35: Diputado Nac. | D35: Frente Propuesta Federal | E35: 71 | J35: Alianza FPV
A36: 4 | B36: ROLON | C36: Diputado Nac. | D36: Blanco | E36: 10 | J36: Alianza Movimiento de Unidad Popular
A37: 4 | B37: ROLON | C37: Diputado Nac. | D37: Nulo | E37: 1 | F37: =SUM(E30:E37) -> 498 | J37: Frente de Integración Pampeana
A38: 5 | B38: TOMAS M DE ANCHORENA | C38: Diputado Nac. | D38: PJ | E38: 47 | G38: 375 | J38: Popular de la Reconstrucción
A39: 5 | B39: TOMAS M DE ANCHORENA | C39: Diputado Nac. | D39: Humanista | E39: 2 | J39: Pueblo Nuevo
A40: 5 | B40: TOMAS M DE ANCHORENA | C40: Diputado Nac. | D40: Pueblo Nuevo | E40: 11 | J40: Junta Vecinal por Catriló
A41: 5 | B41: TOMAS M DE ANCHORENA | C41: Diputado Nac. | D41: Partido de los Trabajadores Soc. | E41: 5 | J41: Junta Vecinal Cambio y Progreso por Lonquimay
A42: 5 | B42: TOMAS M DE ANCHORENA | C42: Diputado Nac. | D42: FREPAM | E42: 179 | J42: Afirmación para una República Igualitaria
...

Sheet 2015-Prov
I3: Categorías | J3: Destino
I4: Intendente | J4: PJ
A5: Circuito | B5: Localidad | C5: Categoria | D5: Destino | E5: Cantidad | F5: TOTAL | G5: PADRON | I5: Concejales | J5: Alianza
A6: 1 | B6: DOBLAS | C6: Intendente | D6: PJ | E6: 454 | I6: Juez de Paz | J6: Blanco
A7: 1 | B7: DOBLAS | C7: Intendente | D7: FREPAM | E7: 318 | I7: Presidente Comisión de Fomento | J7: Humanista
A8: 1 | B8: DOBLAS | C8: Intendente | D8: Punto de Unión Doblense | E8: 415 | I8: Vocales | J8: Acción por la República
A9: 1 | B9: DOBLAS | C9: Intendente | D9: Blanco | E9: 74 | I9: Presidente | J9: Movimiento Federalista Pampeano
A10: 1 | B10: DOBLAS | C10: Intendente | D10: Nulo | E10: 2 | F10: =SUM(E6:E10) -> 1263 | I10: Senador Nac. | J10: Socialismo Auténtico
A11: 1 | B11: DOBLAS | C11: Concejales | D11: PJ | E11: 421 | I11: Diputado Nac. | J11: Frente Pueblo Unido - Socialismo Auténtico
A12: 1 | B12: DOBLAS | C12: Concejales | D12: FREPAM | E12: 269 | I12: Gobernador | J12: Unión Popular de La Adela
A13: 1 | B13: DOBLAS | C13: Concejales | D13: Punto de Unión Doblense | E13: 473 | I13: Diputados Provinciales | J13: Convocatoria Independiente
A14: 1 | B14: DOBLAS | C14: Concejales | D14: Blanco | E14: 98 | J14: Patria Grande
A15: 1 | B15: DOBLAS | C15: Concejales | D15: Nulo | E15: 2 | F15: =SUM(E11:E15) -> 1263 | J15: Alianza Unión por Santa Isabel
A16: 1 | B16: DOBLAS | C16: Juez de Paz | D16: PJ | E16: 386 | J16: Junta Vecinal de Mauricio Mayer
A17: 1 | B17: DOBLAS | C17: Juez de Paz | D17: Punto de Unión Doblense | E17: 632 | J17: Intransigente
A18: 1 | B18: DOBLAS | C18: Juez de Paz | D18: Blanco | E18: 243 | J18: Alianza Victorica Electoral y Programática
A19: 1 | B19: DOBLAS | C19: Juez de Paz | D19: Nulo | E19: 2 | F19: =SUM(E16:E19) -> 1263 | J19: Junta vecinal por y para Ceballos
A20: 2 | B20: MACACHIN | C20: Intendente | D20: PJ | E20: 1730 | J20: Junta Vecinal de Relmo
A21: 2 | B21: MACACHIN | C21: Intendente | D21: GEN | E21: 298 | J21: Unidos por Villa Mirasol
A22: 2 | B22: MACACHIN | C22: Intendente | D22: FREPAM | E22: 1463 | J22: Unión Vecinal Villa Mirasol
A23: 2 | B23: MACACHIN | C23: Intendente | D23: Blanco | E23: 372 | J23: Junta Vecinal por Arauz
A24: 2 | B24: MACACHIN | C24: Intendente | D24: Nulo | E24: 16 | F24: =SUM(E20:E24) -> 3879 | J24: Movimiento Popular Veinticinqueño Juntos por 25
A25: 2 | B25: MACACHIN | C25: Concejales | D25: PJ | E25: 1680 | J25: Unión Vecinal La Maruja
A26: 2 | B26: MACACHIN | C26: Concejales | D26: GEN | E26: 287 | J26: Unión Vecinal de Pichi Huinca
A27: 2 | B27: MACACHIN | C27: Concejales | D27: FREPAM | E27: 1441 | J27: Junta Vecinal de A. Van Praet
A28: 2 | B28: MACACHIN | C28: Concejales | D28: Blanco | E28: 454 | J28: Junta Vecinal de Falucho
A29: 2 | B29: MACACHIN | C29: Concejales | D29: Nulo | E29: 17 | F29: =SUM(E25:E29) -> 3879 | J29: Junta Vecinal Quetrequén Somos Todos
A30: 2 | B30: MACACHIN | C30: Juez de Paz | D30: PJ | E30: 1886 | J30: Junta Vecinal Unión por Metileo
A31: 2 | B31: MACACHIN | C31: Juez de Paz | D31: FREPAM | E31: 1311 | J31: Frente Alternativa Pampeana
A32: 2 | B32: MACACHIN | C32: Juez de Paz | D32: Blanco | E32: 664 | J32: Frente Popular Anguil
A33: 2 | B33: MACACHIN | C33: Juez de Paz | D33: Nulo | E33: 18 | F33: =SUM(E30:E33) -> 3879 | J33: Unidad 25
A34: 3 | B34: MIGUEL RIGLOS | C34: Intendente | D34: PJ | E34: 1067 | J34: Alianza Frente Mapa
A35: 3 | B35: MIGUEL RIGLOS | C35: Intendente | D35: FREPAM | E35: 769 | J35: Alianza FPV
A36: 3 | B36: MIGUEL RIGLOS | C36: Intendente | D36: Blanco | E36: 55 | J36: Alianza Movimiento de Unidad Popular
A37: 3 | B37: MIGUEL RIGLOS | C37: Intendente | D37: Nulo | E37: 1 | F37: =SUM(E34:E37) -> 1892 | J37: Frente de Integración Pampeana
A38: 3 | B38: MIGUEL RIGLOS | C38: Concejales | D38: PJ | E38: 1024 | J38: Popular de la Reconstrucción
A39: 3 | B39: MIGUEL RIGLOS | C39: Concejales | D39: FREPAM | E39: 791 | J39: Pueblo Nuevo
A40: 3 | B40: MIGUEL RIGLOS | C40: Concejales | D40: Blanco | E40: 77 | F40: =SUM(E38:E40) -> 1892 | J40: Junta Vecinal por Catriló
A41: 3 | B41: MIGUEL RIGLOS | C41: Juez de Paz | D41: PJ | E41: 1098 | J41: Junta Vecinal Cambio y Progreso por Lonquimay
A42: 3 | B42: MIGUEL RIGLOS | C42: Juez de Paz | D42: FREPAM | E42: 721 | J42: Afirmación para una República Igualitaria
...

Sheet Tabla dinámica 1
A2: Elección 2015 Categoría LEGISLATIVOS NACIONALES
A5: SUM of Cantidad | B5: Destino | C5: Categoria
B6: Alianza FPV | D6: Cambiemos - FREPAM | F6: Blanco | H6: Pueblo Nuevo | J6: GEN | L6: Nulo
A7: Localidad | B7: Senador Nac. | C7: Diputado Nac. | D7: Senador Nac. | E7: Diputado Nac. | F7: Diputado Nac. | G7: Senador Nac. | H7: Senador Nac. | I7: Diputado Nac. | J7: Senador Nac. | K7: Diputado Nac. | L7: Senador Nac. | M7: Diputado Nac.
A8: SANTA ROSA | B8: 22106 | C8: 21892 | D8: 23505 | E8: 23541 | F8: 14678 | G8: 14296 | H8: 7742 | I8: 7612 | J8: 1841 | K8: 1783 | L8: 561 | M8: 545
A9: GENERAL PICO | B9: 6059 | C9: 6068 | D9: 3416 | E9: 3430 | F9: 4328 | G9: 4283 | H9: 2472 | I9: 2416 | J9: 335 | K9: 322 | L9: 154 | M9: 155
A10: GRAL ACHA | B10: 2132 | C10: 2124 | D10: 2225 | E10: 2164 | F10: 3259 | G10: 3163 | H10: 1137 | I10: 1113 | J10: 90 | K10: 75 | L10: 88 | M10: 100
A11: TOAY | B11: 3138 | C11: 3175 | D11: 2598 | E11: 2580 | F11: 1812 | G11: 1756 | H11: 1019 | I11: 959 | J11: 198 | K11: 183 | L11: 41 | M11: 41
A12: EDUARDO CASTEX | B12: 2993 | C12: 2993 | D12: 2672 | E12: 2642 | F12: 964 | G12: 933 | H12: 469 | I12: 460 | J12: 64 | K12: 65 | L12: 66 | M12: 73
A13: CNIA. 25 DE MAYO | B13: 1997 | C13: 2283 | D13: 759 | E13: 734 | F13: 2143 | G13: 2375 | H13: 636 | I13: 605 | J13: 97 | K13: 96 | L13: 50 | M13: 53
A14: INT. ALVEAR | B14: 1757 | C14: 1780 | D14: 2210 | E14: 2193 | F14: 1222 | G14: 1218 | H14: 388 | I14: 369 | J14: 59 | K14: 68 | L14: 191 | M14: 191
A15: REALICO | B15: 2253 | C15: 2241 | D15: 2096 | E15: 2032 | F15: 918 | G15: 830 | H15: 294 | I15: 287 | J15: 56 | K15: 52 | L15: 15 | M15: 14
A16: VICTORICA | B16: 2093 | C16: 2081 | D16: 826 | E16: 830 | F16: 1260 | G16: 1245 | H16: 240 | I16: 237 | J16: 53 | K16: 51 | L16: 146 | M16: 144
A17: MACACHIN | B17: 1596 | C17: 1596 | D17: 1306 | E17: 1304 | F17: 585 | G17: 543 | H17: 227 | I17: 191 | J17: 178 | K17: 175 | L17: 16 | M17: 15
A18: ING. LUIGGI | B18: 1531 | C18: 1519 | D18: 1066 | E18: 1076 | F18: 553 | G18: 538 | H18: 219 | I18: 211 | J18: 69 | K18: 64 | L18: 22 | M18: 22
A19: CATRILO | B19: 1330 | C19: 1322 | D19: 1076 | E19: 1069 | F19: 528 | G19: 513 | H19: 189 | I19: 190 | J19: 17 | K19: 16 | L19: 9 | M19: 9
... A98: Total general | B98: 73268 | C98: 73243 | D98: 64254 | E98: 63946 | F98: 42312 | G98: 41312 | H98: 18252 | I98: 17759 | J98: 3665 | K98: 3521 | L98: 1559 | M98: 1529

Sheet 2015-Primarias
I3: Categorías | J3: Destino
I4: Intendente | J4: PJ
A5: Circuito | B5: Localidad | C5: Categoria | D5: Destino | E5: Cantidad | F5: TOTAL | G5: PADRON | I5: Concejales | J5: Alianza
A6: 9 y 10 | B6: SANTA ROSA | C6: Presidente | D6: Movimiento al Socialismo | E6: 437 | G6: =41964+46705 -> 88669 | I6: Juez de Paz | J6: Blanco
A7: 9 y 10 | B7: SANTA ROSA | C7: Presidente | D7: Socialismo Auténtico | E7: 0 | I7: Presidente Comisión de Fomento | J7: Humanista
A8: 9 y 10 | B8: SANTA ROSA | C8: Presidente | D8: Movimiento de Acción Vecinal | E8: 151 | I8: Vocales | J8: Acción por la República
A9: 9 y 10 | B9: SANTA ROSA | C9: Presidente | D9: Partido Popular | E9: 163 | I9: Presidente | J9: Movimiento Federalista Pampeano
A10: 9 y 10 | B10: SANTA ROSA | C10: Presidente | D10: Alianza FPV | E10: 25113 | I10: Senador Nac. | J10: Socialismo Auténtico
A11: 9 y 10 | B11: SANTA ROSA | C11: Presidente | D11: GEN | E11: 2363 | I11: Diputado Nac. | J11: Frente Pueblo Unido - Socialismo Auténtico
A12: 9 y 10 | B12: SANTA ROSA | C12: Presidente | D12: Alianza Compromiso Federal | E12: 1155 | J12: Unión Popular de La Adela
A13: 9 y 10 | B13: SANTA ROSA | C13: Presidente | D13: Nueva Izquierda | E13: 270 | J13: Convocatoria Independiente
A14: 9 y 10 | B14: SANTA ROSA | C14: Presidente | D14: Cambiemos - FREPAM | E14: 21560 | J14: Movimiento al Socialismo
A15: 9 y 10 | B15: SANTA ROSA | C15: Presidente | D15: Frente Popular | E15: 386 | J15: Movimiento de Acción Vecinal
A16: 9 y 10 | B16: SANTA ROSA | C16: Presidente | D16: Frente de Izquierda y de los Trabajadores | E16: 1805 | J16: Partido Popular
A17: 9 y 10 | B17: SANTA ROSA | C17: Presidente | D17: Unidos por una Nueva Alternativa | E17: 10462 | J17: Nueva Izquierda
A18: 9 y 10 | B18: SANTA ROSA | C18: Presidente | D18: Blanco | E18: 2421 | J18: Frente Popular
A19: 9 y 10 | B19: SANTA ROSA | C19: Presidente | D19: Nulo | E19: 1016 | F19: =SUM(E6:E19) -> 67302 | J19: Unidos por una Nueva Alternativa
A20: 9 y 10 | B20: SANTA ROSA | C20: Senador Nac. | D20: Socialismo Auténtico | E20: 436 | J20: Patria Grande
A21: 9 y 10 | B21: SANTA ROSA | C21: Senador Nac. | D21: Alianza FPV | E21: 26061 | J21: Alianza Unión por Santa Isabel
A22: 9 y 10 | B22: SANTA ROSA | C22: Senador Nac. | D22: GEN | E22: 1786 | J22: Junta Vecinal de Mauricio Mayer
A23: 9 y 10 | B23: SANTA ROSA | C23: Senador Nac. | D23: Cambiemos - FREPAM | E23: 23349 | J23: Intransigente
A24: 9 y 10 | B24: SANTA ROSA | C24: Senador Nac. | D24: Frente de Izquierda y de los Trabajadores | E24: 1366 | J24: Alianza Victorica Electoral y Programática
A25: 9 y 10 | B25: SANTA ROSA | C25: Senador Nac. | D25: Unidos por una Nueva Alternativa | E25: 6974 | J25: Junta vecinal por y para Ceballos
A26: 9 y 10 | B26: SANTA ROSA | C26: Senador Nac. | D26: Blanco | E26: 6434 | J26: Junta Vecinal de Relmo
A27: 9 y 10 | B27: SANTA ROSA | C27: Senador Nac. | D27: Nulo | E27: 896 | F27: =SUM(E20:E27) -> 67302 | J27: Unidos por Villa Mirasol
A28: 9 y 10 | B28: SANTA ROSA | C28: Diputado Nac. | D28: Socialismo Auténtico | E28: 503 | J28: Unión Vecinal Villa Mirasol
A29: 9 y 10 | B29: SANTA ROSA | C29: Diputado Nac. | D29: Alianza FPV | E29: 25597 | J29: Junta Vecinal por Arauz
A30: 9 y 10 | B30: SANTA ROSA | C30: Diputado Nac. | D30: GEN | E30: 1811 | J30: Movimiento Popular Veinticinqueño Juntos por 25
A31: 9 y 10 | B31: SANTA ROSA | C31: Diputado Nac. | D31: Cambiemos - FREPAM | E31: 22647 | J31: Unión Vecinal La Maruja
A32: 9 y 10 | B32: SANTA ROSA | C32: Diputado Nac. | D32: Frente de Izquierda y de los Trabajadores | E32: 1554 | J32: Unión Vecinal de Pichi Huinca
A33: 9 y 10 | B33: SANTA ROSA | C33: Diputado Nac. | D33: Unidos por una Nueva Alternativa | E33: 7023 | J33: Junta Vecinal de A. Van Praet
A34: 9 y 10 | B34: SANTA ROSA | C34: Diputado Nac. | D34: Blanco | E34: 7299 | J34: Junta Vecinal de Falucho
A35: 9 y 10 | B35: SANTA ROSA | C35: Diputado Nac. | D35: Nulo | E35: 868 | F35: =SUM(E28:E35) -> 67302 | J35: Junta Vecinal Quetrequén Somos Todos
A36: 57 y 58 | B36: GENERAL PICO | C36: Presidente | D36: Movimiento al Socialismo | E36: 166 | G36: =28399+20324 -> 48723 | J36: Junta Vecinal Unión por Metileo
A37: 57 y 58 | B37: GENERAL PICO | C37: Presidente | D37: Socialismo Auténtico | E37: 0 | J37: Frente Alternativa Pampeana
A38: 57 y 58 | B38: GENERAL PICO | C38: Presidente | D38: Movimiento de Acción Vecinal | E38: 74 | J38: Frente Popular Anguil
A39: 57 y 58 | B39: GENERAL PICO | C39: Presidente | D39: Partido Popular | E39: 92 | J39: Unidad 25
A40: 57 y 58 | B40: GENERAL PICO | C40: Presidente | D40: Alianza FPV | E40: 13874 | J40: Alianza Frente Mapa
A41: 57 y 58 | B41: GENERAL PICO | C41: Presidente | D41: GEN | E41: 1070 | J41: Alianza FPV
A42: 57 y 58 | B42: GENERAL PICO | C42: Presidente | D42: Alianza Compromiso Federal | E42: 1041 | J42: Alianza Movimiento de Unidad Popular
...

Sheet Tabla dinámica 2
C3: ELECCION | D3: CATEGORIA
C4: 2017 PRIMARIA | E4: 2017GRAL | G4: 2019GRAL
C5: Diputado Nac. | E5: Diputado Nac.
A6: LOCALIDAD | B6: DESTINO | C6: Votos | D6: % | E6: Votos | F6: % | G6: Votos | H6: %
A7: SANTA ROSA | C7: 65254 | D7: 0.34105116 | E7: 68264 | F7: 0.31174335 | G7: 131130 | H7: 0.30310946
A8: GENERAL PICO | B8: 1 - PJ | C8: 6373 | D8: 0.29897729 | E8: 16854 | F8: 0.40855211 | G8: 36636 | H8: 0.47850165
B9: 2 - Frepam | C9: 12613 | D9: 0.59171514 | E9: 21991 | F9: 0.53307638 | G9: 22747 | H9: 0.29709785
B10: 3 - Otros | C10: 1170 | D10: 0.054888347 | E10: 1783 | F10: 0.043221099 | G10: 13211 | H10: 0.17254846
B11: 4 - Blanco/Nulo | C11: 1160 | D11: 0.054419216 | E11: 625 | F11: 0.015150413 | G11: 3970 | H11: 0.051852045
A12: Total GENERAL PICO | C12: 21316 | D12: 0.11140844 | E12: 41253 | F12: 0.18839137 | G12: 76564 | H12: 0.17697912 | K12: =9128+7839 -> 16967
A13: TOAY | B13: 1 - PJ | C13: 3678 | D13: 0.40880293 | E13: 4247 | F13: 0.46364629 | G13: 10328 | H13: 0.5470339
B14: 2 - Frepam | C14: 4242 | D14: 0.4714905 | E14: 4046 | F14: 0.44170306 | G14: 4131 | H14: 0.21880297
B15: 3 - Otros | C15: 621 | D15: 0.069023008 | E15: 602 | F15: 0.065720524 | G15: 3495 | H15: 0.18511653
B16: 4 - Blanco/Nulo | C16: 456 | D16: 0.050683561 | E16: 265 | F16: 0.028930131 | G16: 926 | H16: 0.04904661
A17: Total TOAY | C17: 8997 | D17: 0.047022976 | E17: 9160 | F17: 0.041831259 | G17: 18880 | H17: 0.043641474
A18: GRAL ACHA | B18: 1 - PJ | C18: 2319 | D18: 0.2851697 | E18: 3096 | F18: 0.35945664 | G18: 5764 | H18: 0.32668329
B19: 2 - Frepam | C19: 4767 | D19: 0.58620266 | E19: 4717 | F19: 0.54766051 | G19: 5961 | H19: 0.33784856
B20: 3 - Otros | C20: 379 | D20: 0.046606001 | E20: 457 | F20: 0.053059329 | G20: 3998 | H20: 0.22659261
B21: 4 - Blanco/Nulo | C21: 667 | D21: 0.082021643 | E21: 343 | F21: 0.039823523 | G21: 1921 | H21: 0.10887554
A22: Total GRAL ACHA | C22: 8132 | D22: 0.042502038 | E22: 8613 | F22: 0.039333257 | G22: 17644 | H22: 0.040784437
A23: EDUARDO CASTEX | B23: 1 - PJ | C23: 2488 | D23: 0.38247502 | E23: 3100 | F23: 0.47980189 | G23: 5628 | H23: 0.40582636
B24: 2 - Frepam | C24: 3365 | D24: 0.51729439 | E24: 2839 | F24: 0.43940566 | G24: 5761 | H24: 0.41541679
B25: 3 - Otros | C25: 267 | D25: 0.04104535 | E25: 298 | F25: 0.046122891 | G25: 1890 | H25: 0.13628497
B26: 4 - Blanco/Nulo | C26: 385 | D26: 0.059185242 | E26: 224 | F26: 0.034669556 | G26: 589 | H26: 0.042471878
A27: Total EDUARDO CASTEX | C27: 6505 | D27: 0.033998495 | E27: 6461 | F27: 0.029505651 | G27: 13868 | H27: 0.032056142
A28: CNIA. 25 DE MAYO | B28: 1 - PJ | C28: 2016 | D28: 0.38458604 | E28: 2917 | F28: 0.48495428 | G28: 5936 | H28: 0.49171637
B29: 2 - Frepam | C29: 2534 | D29: 0.48340328 | E29: 2548 | F29: 0.42360765 | G29: 2113 | H29: 0.17503313
B30: 3 - Otros | C30: 280 | D30: 0.053414727 | E30: 339 | F30: 0.056359102 | G30: 2206 | H30: 0.18273691
B31: 4 - Blanco/Nulo | C31: 412 | D31: 0.078595956 | E31: 211 | F31: 0.035078969 | G31: 1817 | H31: 0.15051359
A32: Total CNIA. 25 DE MAYO | C32: 5242 | D32: 0.027397403 | E32: 6015 | F32: 0.027468889 | G32: 12072 | H32: 0.027904654
A33: INT. ALVEAR | B33: 1 - PJ | C33: 1706 | D33: 0.31739535 | E33: 2257 | F33: 0.40542482 | G33: 6213 | H33: 0.53166182
B34: 2 - Frepam | C34: 3201 | D34: 0.59553488 | E34: 2971 | F34: 0.53368062 | G34: 1590 | H34: 0.13606024
B35: 3 - Otros | C35: 182 | D35: 0.033860465 | E35: 200 | F35: 0.035925992 | G35: 2892 | H35: 0.24747561
B36: 4 - Blanco/Nulo | C36: 286 | D36: 0.053209302 | E36: 139 | F36: 0.024968565 | G36: 991 | H36: 0.084802328
A37: Total INT. ALVEAR | C37: 5375 | D37: 0.02809253 | E37: 5567 | F37: 0.025422993 | G37: 11686 | H37: 0.027012408
A38: REALICO | B38: 1 - PJ | C38: 1930 | D38: 0.38400318 | E38: 2177 | F38: 0.41466667 | G38: 5538 | H38: 0.51506696
B39: 2 - Frepam | C39: 2512 | D39: 0.49980103 | E39: 2701 | F39: 0.51447619 | G39: 3854 | H39: 0.35844494
B40: 3 - Otros | C40: 210 | D40: 0.04178273 | E40: 201 | F40: 0.038285714 | G40: 821 | H40: 0.076357887
B41: 4 - Blanco/Nulo | C41: 374 | D41: 0.074413052 | E41: 171 | F41: 0.032571429 | G41: 539 | H41: 0.050130208
A42: Total REALICO | C42: 5026 | D42: 0.026268476 | E42: 5250 | F42: 0.02397534 | G42: 10752 | H42: 0.02485345
...

Sheet 2017-General
I1: Categorías | J1: Destino
I2: Intendente | J2: PJ
A3: Circuito | B3: Localidad | C3: Categoria | D3: Destino | E3: Cantidad | F3: TOTAL | G3: PADRON | I3: Concejales | J3: Alianza
A4: 1 | B4: DOBLAS | C4: Diputado Nac. | D4: PJ | E4: 489 | G4: 1505 | I4: Juez de Paz | J4: Blanco
A5: 1 | B5: DOBLAS | C5: Diputado Nac. | D5: Humanista | E5: 19 | I5: Presidente Comisión de Fomento | J5: Humanista
A6: 1 | B6: DOBLAS | C6: Diputado Nac. | D6: Partido de los Trabajadores Soc. | E6: 10 | I6: Vocales | J6: Acción por la República
A7: 1 | B7: DOBLAS | C7: Diputado Nac. | D7: FREPAM | E7: 19 | I7: Presidente | J7: Movimiento Federalista Pampeano
A8: 1 | B8: DOBLAS | C8: Diputado Nac. | D8: Izquierda al Frente por el Soc. | E8: 14 | I8: Senador Nac. | J8: Socialismo Auténtico
A9: 1 | B9: DOBLAS | C9: Diputado Nac. | D9: Cambiemos | E9: 548 | I9: Diputado Nac. | J9: Frente Pueblo Unido - Socialismo Auténtico
A10: 1 | B10: DOBLAS | C10: Diputado Nac. | D10: Nulo | E10: 44 | J10: Unión Popular de La Adela
A11: 1 | B11: DOBLAS | C11: Diputado Nac. | D11: Blanco | E11: 13 | F11: 1156 | J11: Convocatoria Independiente
A12: 2 | B12: MACACHIN | C12: Diputado Nac. | D12: PJ | E12: 1806 | G12: 4555 | J12: Patria Grande
A13: 2 | B13: MACACHIN | C13: Diputado Nac. | D13: Humanista | E13: 32 | J13: Alianza Unión por Santa Isabel
A14: 2 | B14: MACACHIN | C14: Diputado Nac. | D14: Partido de los Trabajadores Soc. | E14: 33 | J14: Junta Vecinal de Mauricio Mayer
A15: 2 | B15: MACACHIN | C15: Diputado Nac. | D15: FREPAM | E15: 53 | J15: Intransigente
A16: 2 | B16: MACACHIN | C16: Diputado Nac. | D16: Izquierda al Frente por el Soc. | E16: 42 | J16: Alianza Victorica Electoral y Programática
A17: 2 | B17: MACACHIN | C17: Diputado Nac. | D17: Cambiemos | E17: 1721 | J17: Junta vecinal por y para Ceballos
A18: 2 | B18: MACACHIN | C18: Diputado Nac. | D18: Nulo | E18: 61 | J18: Junta Vecinal de Relmo
A19: 2 | B19: MACACHIN | C19: Diputado Nac. | D19: Blanco | E19: 43 | F19: 3791 | J19: Unidos por Villa Mirasol
A20: 3 | B20: MIGUEL RIGLOS | C20: Diputado Nac. | D20: PJ | E20: 976 | G20: 2174 | J20: Unión Vecinal Villa Mirasol
A21: 3 | B21: MIGUEL RIGLOS | C21: Diputado Nac. | D21: Humanista | E21: 11 | J21: Junta Vecinal por Arauz
A22: 3 | B22: MIGUEL RIGLOS | C22: Diputado Nac. | D22: Partido de los Trabajadores Soc. | E22: 12 | J22: Movimiento Popular Veinticinqueño Juntos por 25
A23: 3 | B23: MIGUEL RIGLOS | C23: Diputado Nac. | D23: FREPAM | E23: 13 | J23: Unión Vecinal La Maruja
A24: 3 | B24: MIGUEL RIGLOS | C24: Diputado Nac. | D24: Izquierda al Frente por el Soc. | E24: 10 | J24: Unión Vecinal de Pichi Huinca
A25: 3 | B25: MIGUEL RIGLOS | C25: Diputado Nac. | D25: Cambiemos | E25: 686 | J25: Junta Vecinal de A. Van Praet
A26: 3 | B26: MIGUEL RIGLOS | C26: Diputado Nac. | D26: Nulo | E26: 15 | J26: Junta Vecinal de Falucho
A27: 3 | B27: MIGUEL RIGLOS | C27: Diputado Nac. | D27: Blanco | E27: 13 | F27: 1736 | J27: Junta Vecinal Quetrequén Somos Todos
A28: 4 | B28: ROLON | C28: Diputado Nac. | D28: PJ | E28: 309 | G28: 659 | J28: Junta Vecinal Unión por Metileo
A29: 4 | B29: ROLON | C29: Diputado Nac. | D29: Humanista | E29: 4 | J29: Frente Alternativa Pampeana
A30: 4 | B30: ROLON | C30: Diputado Nac. | D30: Partido de los Trabajadores Soc. | E30: 1 | J30: Frente Popular Anguil
A31: 4 | B31: ROLON | C31: Diputado Nac. | D31: FREPAM | E31: 1 | J31: Unidad 25
A32: 4 | B32: ROLON | C32: Diputado Nac. | D32: Izquierda al Frente por el Soc. | E32: 10 | J32: Alianza Frente Mapa
A33: 4 | B33: ROLON | C33: Diputado Nac. | D33: Cambiemos | E33: 203 | J33: Alianza FPV
A34: 4 | B34: ROLON | C34: Diputado Nac. | D34: Nulo | E34: 4 | J34: Alianza Movimiento de Unidad Popular
A35: 4 | B35: ROLON | C35: Diputado Nac. | D35: Blanco | E35: 13 | F35: 545 | J35: Frente de Integración Pampeana
A36: 5 | B36: TOMAS M DE ANCHORENA | C36: Diputado Nac. | D36: PJ | E36: 119 | G36: 388 | J36: Popular de la Reconstrucción
A37: 5 | B37: TOMAS M DE ANCHORENA | C37: Diputado Nac. | D37: Humanista | E37: 1 | J37: Pueblo Nuevo
A38: 5 | B38: TOMAS M DE ANCHORENA | C38: Diputado Nac. | D38: Partido de los Trabajadores Soc. | E38: 2 | J38: Junta Vecinal por Catriló
A39: 5 | B39: TOMAS M DE ANCHORENA | C39: Diputado Nac. | D39: FREPAM | E39: 4 | J39: Junta Vecinal Cambio y Progreso por Lonquimay
A40: 5 | B40: TOMAS M DE ANCHORENA | C40: Diputado Nac. | D40: Izquierda al Frente por el Soc. | E40: 1 | J40: Afirmación para una República Igualitaria
...

Sheet 2019-Prov
I3: Categorías | J3: Destino
I4: Intendente | J4: PJ
A5: Circuito | B5: Localidad | C5: Categoria | D5: Destino | E5: Cantidad | F5: TOTAL | G5: PADRON | I5: Concejales | J5: Alianza
A6: 1 | B6: DOBLAS | C6: Intendente | D6: Frente justicialista pampeano | E6: 477 | I6: Juez de Paz | J6: Blanco
A7: 1 | B7: DOBLAS | C7: Intendente | D7: Cambiemos - FREPAM | E7: 316 | I7: Presidente Comisión de Fomento | J7: Humanista
A8: 1 | B8: DOBLAS | C8: Intendente | D8: Comunidad organizada | E8: 308 | I8: Vocales | J8: Acción por la República
A9: 1 | B9: DOBLAS | C9: Intendente | D9: Frente popular pampeano | E9: 92 | I9: Presidente | J9: Movimiento Federalista Pampeano
A10: 1 | B10: DOBLAS | C10: Intendente | D10: Blanco | E10: 49 | F10: =SUM(E6:E11) -> 1249 | I10: Senador Nac. | J10: Socialismo Auténtico
A11: 1 | B11: DOBLAS | C11: Intendente | D11: Nulo | E11: 7 | I11: Diputado Nac. | J11: Frente Pueblo Unido - Socialismo Auténtico
A12: 1 | B12: DOBLAS | C12: Diputados Provinciales | D12: Frente justicialista pampeano | E12: 419 | I12: Gobernador | J12: Unión Popular de La Adela
A13: 1 | B13: DOBLAS | C13: Diputados Provinciales | D13: Cambiemos - FREPAM | E13: 346 | I13: Diputados Provinciales | J13: Convocatoria Independiente
A14: 1 | B14: DOBLAS | C14: Diputados Provinciales | D14: Comunidad organizada | E14: 230 | J14: Patria Grande
A15: 1 | B15: DOBLAS | C15: Diputados Provinciales | D15: Blanco | E15: 167 | J15: Alianza Unión por Santa Isabel
A16: 1 | B16: DOBLAS | C16: Diputados Provinciales | D16: Frente popular pampeano | E16: 60 | F16: =SUM(E12:E21) -> 1249 | J16: Junta Vecinal de Mauricio Mayer
A17: 1 | B17: DOBLAS | C17: Diputados Provinciales | D17: Partido socialista | E17: 8 | J17: Intransigente
A18: 1 | B18: DOBLAS | C18: Diputados Provinciales | D18: Nulo | E18: 8 | J18: Alianza Victorica Electoral y Programática
A19: 1 | B19: DOBLAS | C19: Diputados Provinciales | D19: Pueblo Nuevo | E19: 6 | J19: Junta vecinal por y para Ceballos
A20: 1 | B20: DOBLAS | C20: Diputados Provinciales | D20: Desde el pie | E20: 3 | J20: Junta Vecinal de Relmo
A21: 1 | B21: DOBLAS | C21: Diputados Provinciales | D21: Movimiento socialista de los trabajadores | E21: 2 | J21: Unidos por Villa Mirasol
A22: 1 | B22: DOBLAS | C22: Gobernador | D22: Frente justicialista pampeano | E22: 456 | J22: Unión Vecinal Villa Mirasol
A23: 1 | B23: DOBLAS | C23: Gobernador | D23: Cambiemos - FREPAM | E23: 369 | J23: Junta Vecinal por Arauz
A24: 1 | B24: DOBLAS | C24: Gobernador | D24: Comunidad organizada | E24: 241 | J24: Movimiento Popular Veinticinqueño Juntos por 25
A25: 1 | B25: DOBLAS | C25: Gobernador | D25: Blanco | E25: 98 | J25: Unión Vecinal La Maruja
